{
 "cells": [
  {
   "cell_type": "markdown",
   "id": "161aa5bb-8421-43ee-8df4-3c0a2be63c29",
   "metadata": {},
   "source": [
    "# Review data preparation"
   ]
  },
  {
   "cell_type": "code",
   "execution_count": 1,
   "id": "c3609e61-6a6a-4123-8eef-6a5741f5006e",
   "metadata": {},
   "outputs": [
    {
     "name": "stderr",
     "output_type": "stream",
     "text": [
      "[nltk_data] Downloading package wordnet to\n",
      "[nltk_data]     /Users/nickolaspedrimiranda/nltk_data...\n",
      "[nltk_data]   Package wordnet is already up-to-date!\n",
      "[nltk_data] Downloading package omw-1.4 to\n",
      "[nltk_data]     /Users/nickolaspedrimiranda/nltk_data...\n",
      "[nltk_data]   Package omw-1.4 is already up-to-date!\n"
     ]
    }
   ],
   "source": [
    "%load_ext autoreload\n",
    "%autoreload 2\n",
    "\n",
    "# Import ds libraries\n",
    "import pandas as pd\n",
    "import numpy as np\n",
    "import re\n",
    "\n",
    "from datetime import datetime, timedelta\n",
    "\n",
    "# Import acquire functions\n",
    "import nick_acquire as a\n",
    "import nick_prepare as prep"
   ]
  },
  {
   "cell_type": "code",
   "execution_count": 2,
   "id": "016606a4-b675-477b-a074-1a5a63ca0448",
   "metadata": {},
   "outputs": [],
   "source": [
    "api_reviews = pd.read_csv('reviews_progress.csv')\n",
    "scrape_reviews = pd.read_csv('scraped_reviews.csv')"
   ]
  },
  {
   "cell_type": "code",
   "execution_count": 3,
   "id": "3ab6e992-56f2-4717-bfdc-c5862c06c347",
   "metadata": {},
   "outputs": [
    {
     "data": {
      "text/html": [
       "<div>\n",
       "<style scoped>\n",
       "    .dataframe tbody tr th:only-of-type {\n",
       "        vertical-align: middle;\n",
       "    }\n",
       "\n",
       "    .dataframe tbody tr th {\n",
       "        vertical-align: top;\n",
       "    }\n",
       "\n",
       "    .dataframe thead th {\n",
       "        text-align: right;\n",
       "    }\n",
       "</style>\n",
       "<table border=\"1\" class=\"dataframe\">\n",
       "  <thead>\n",
       "    <tr style=\"text-align: right;\">\n",
       "      <th></th>\n",
       "      <th>camis</th>\n",
       "      <th>place_id</th>\n",
       "      <th>review_id</th>\n",
       "      <th>review_relative_time</th>\n",
       "      <th>review_rating</th>\n",
       "      <th>review_text</th>\n",
       "      <th>review_language</th>\n",
       "      <th>author_display_name</th>\n",
       "      <th>contributor_id</th>\n",
       "      <th>author_photo_uri</th>\n",
       "      <th>publish_time</th>\n",
       "    </tr>\n",
       "  </thead>\n",
       "  <tbody>\n",
       "    <tr>\n",
       "      <th>0</th>\n",
       "      <td>41168748</td>\n",
       "      <td>ChIJNzTkzav1wokRg3R8aGzuiWI</td>\n",
       "      <td>ChdDSUhNMG9nS0VJQ0FnSURHd09qaWxBRRAB</td>\n",
       "      <td>a year ago</td>\n",
       "      <td>5</td>\n",
       "      <td>These Guys are really professional. Well behav...</td>\n",
       "      <td>en</td>\n",
       "      <td>Md Omar Faruk</td>\n",
       "      <td>113263009121414123208</td>\n",
       "      <td>https://lh3.googleusercontent.com/a-/ALV-UjWGD...</td>\n",
       "      <td>2021-11-14T20:50:12Z</td>\n",
       "    </tr>\n",
       "    <tr>\n",
       "      <th>1</th>\n",
       "      <td>41168748</td>\n",
       "      <td>ChIJNzTkzav1wokRg3R8aGzuiWI</td>\n",
       "      <td>ChdDSUhNMG9nS0VJQ0FnSUMyMzlTUXpnRRAB</td>\n",
       "      <td>a year ago</td>\n",
       "      <td>1</td>\n",
       "      <td>I haven't had Dunkin Donuts in years. Being th...</td>\n",
       "      <td>en</td>\n",
       "      <td>Hipolito Rivera</td>\n",
       "      <td>102916427998123407326</td>\n",
       "      <td>https://lh3.googleusercontent.com/a-/ALV-UjUN8...</td>\n",
       "      <td>2022-05-02T09:47:34Z</td>\n",
       "    </tr>\n",
       "    <tr>\n",
       "      <th>2</th>\n",
       "      <td>41168748</td>\n",
       "      <td>ChIJNzTkzav1wokRg3R8aGzuiWI</td>\n",
       "      <td>ChdDSUhNMG9nS0VJQ0FnSURrN2VDU3RRRRAB</td>\n",
       "      <td>2 years ago</td>\n",
       "      <td>5</td>\n",
       "      <td>This Dunkin is nice, but it's located inside a...</td>\n",
       "      <td>en</td>\n",
       "      <td>DeeAnn Phillips</td>\n",
       "      <td>104489576491114386805</td>\n",
       "      <td>https://lh3.googleusercontent.com/a/ACg8ocL6Fa...</td>\n",
       "      <td>2021-05-22T23:23:44Z</td>\n",
       "    </tr>\n",
       "  </tbody>\n",
       "</table>\n",
       "</div>"
      ],
      "text/plain": [
       "      camis                     place_id  \\\n",
       "0  41168748  ChIJNzTkzav1wokRg3R8aGzuiWI   \n",
       "1  41168748  ChIJNzTkzav1wokRg3R8aGzuiWI   \n",
       "2  41168748  ChIJNzTkzav1wokRg3R8aGzuiWI   \n",
       "\n",
       "                              review_id review_relative_time  review_rating  \\\n",
       "0  ChdDSUhNMG9nS0VJQ0FnSURHd09qaWxBRRAB           a year ago              5   \n",
       "1  ChdDSUhNMG9nS0VJQ0FnSUMyMzlTUXpnRRAB           a year ago              1   \n",
       "2  ChdDSUhNMG9nS0VJQ0FnSURrN2VDU3RRRRAB          2 years ago              5   \n",
       "\n",
       "                                         review_text review_language  \\\n",
       "0  These Guys are really professional. Well behav...              en   \n",
       "1  I haven't had Dunkin Donuts in years. Being th...              en   \n",
       "2  This Dunkin is nice, but it's located inside a...              en   \n",
       "\n",
       "  author_display_name         contributor_id  \\\n",
       "0       Md Omar Faruk  113263009121414123208   \n",
       "1     Hipolito Rivera  102916427998123407326   \n",
       "2     DeeAnn Phillips  104489576491114386805   \n",
       "\n",
       "                                    author_photo_uri          publish_time  \n",
       "0  https://lh3.googleusercontent.com/a-/ALV-UjWGD...  2021-11-14T20:50:12Z  \n",
       "1  https://lh3.googleusercontent.com/a-/ALV-UjUN8...  2022-05-02T09:47:34Z  \n",
       "2  https://lh3.googleusercontent.com/a/ACg8ocL6Fa...  2021-05-22T23:23:44Z  "
      ]
     },
     "execution_count": 3,
     "metadata": {},
     "output_type": "execute_result"
    }
   ],
   "source": [
    "api_reviews.head(3)"
   ]
  },
  {
   "cell_type": "code",
   "execution_count": null,
   "id": "ebf6b60f-d41a-4c48-aec7-2abce79d31a0",
   "metadata": {},
   "outputs": [],
   "source": []
  },
  {
   "cell_type": "code",
   "execution_count": 4,
   "id": "8ded3fdd-9367-4fdf-a68c-7749fafcfc1a",
   "metadata": {},
   "outputs": [
    {
     "data": {
      "text/html": [
       "<div>\n",
       "<style scoped>\n",
       "    .dataframe tbody tr th:only-of-type {\n",
       "        vertical-align: middle;\n",
       "    }\n",
       "\n",
       "    .dataframe tbody tr th {\n",
       "        vertical-align: top;\n",
       "    }\n",
       "\n",
       "    .dataframe thead th {\n",
       "        text-align: right;\n",
       "    }\n",
       "</style>\n",
       "<table border=\"1\" class=\"dataframe\">\n",
       "  <thead>\n",
       "    <tr style=\"text-align: right;\">\n",
       "      <th></th>\n",
       "      <th>camis</th>\n",
       "      <th>publish_time</th>\n",
       "      <th>review_text</th>\n",
       "      <th>review_rating</th>\n",
       "    </tr>\n",
       "  </thead>\n",
       "  <tbody>\n",
       "    <tr>\n",
       "      <th>0</th>\n",
       "      <td>41168748</td>\n",
       "      <td>2021-11-14T20:50:12Z</td>\n",
       "      <td>These Guys are really professional. Well behav...</td>\n",
       "      <td>5</td>\n",
       "    </tr>\n",
       "    <tr>\n",
       "      <th>1</th>\n",
       "      <td>41168748</td>\n",
       "      <td>2022-05-02T09:47:34Z</td>\n",
       "      <td>I haven't had Dunkin Donuts in years. Being th...</td>\n",
       "      <td>1</td>\n",
       "    </tr>\n",
       "    <tr>\n",
       "      <th>2</th>\n",
       "      <td>41168748</td>\n",
       "      <td>2021-05-22T23:23:44Z</td>\n",
       "      <td>This Dunkin is nice, but it's located inside a...</td>\n",
       "      <td>5</td>\n",
       "    </tr>\n",
       "    <tr>\n",
       "      <th>3</th>\n",
       "      <td>41168748</td>\n",
       "      <td>2021-08-17T02:55:05Z</td>\n",
       "      <td>Ordered a box of joes they tried to cheat with...</td>\n",
       "      <td>2</td>\n",
       "    </tr>\n",
       "    <tr>\n",
       "      <th>4</th>\n",
       "      <td>41168748</td>\n",
       "      <td>2023-03-06T16:17:03Z</td>\n",
       "      <td>Another review  my daughter and friends  love ...</td>\n",
       "      <td>4</td>\n",
       "    </tr>\n",
       "    <tr>\n",
       "      <th>...</th>\n",
       "      <td>...</td>\n",
       "      <td>...</td>\n",
       "      <td>...</td>\n",
       "      <td>...</td>\n",
       "    </tr>\n",
       "    <tr>\n",
       "      <th>43867</th>\n",
       "      <td>50107528</td>\n",
       "      <td>2023-05-24T21:33:14Z</td>\n",
       "      <td>Easy to locate, great customer service. Went i...</td>\n",
       "      <td>2</td>\n",
       "    </tr>\n",
       "    <tr>\n",
       "      <th>43868</th>\n",
       "      <td>50107528</td>\n",
       "      <td>2023-07-16T04:20:30Z</td>\n",
       "      <td>A solid doner kebab. Good cuts of lamb and ple...</td>\n",
       "      <td>4</td>\n",
       "    </tr>\n",
       "    <tr>\n",
       "      <th>43869</th>\n",
       "      <td>50107528</td>\n",
       "      <td>2023-05-09T18:27:59Z</td>\n",
       "      <td>We spent 5 days in NYC eating a lot of great (...</td>\n",
       "      <td>5</td>\n",
       "    </tr>\n",
       "    <tr>\n",
       "      <th>43870</th>\n",
       "      <td>50107528</td>\n",
       "      <td>2023-03-05T21:48:09Z</td>\n",
       "      <td>Extremely authentic. Staff/owner is from Turke...</td>\n",
       "      <td>5</td>\n",
       "    </tr>\n",
       "    <tr>\n",
       "      <th>43871</th>\n",
       "      <td>50107528</td>\n",
       "      <td>2023-10-23T13:20:31Z</td>\n",
       "      <td>The chicken is very tender, fresh Turkish brea...</td>\n",
       "      <td>5</td>\n",
       "    </tr>\n",
       "  </tbody>\n",
       "</table>\n",
       "<p>43872 rows × 4 columns</p>\n",
       "</div>"
      ],
      "text/plain": [
       "          camis          publish_time  \\\n",
       "0      41168748  2021-11-14T20:50:12Z   \n",
       "1      41168748  2022-05-02T09:47:34Z   \n",
       "2      41168748  2021-05-22T23:23:44Z   \n",
       "3      41168748  2021-08-17T02:55:05Z   \n",
       "4      41168748  2023-03-06T16:17:03Z   \n",
       "...         ...                   ...   \n",
       "43867  50107528  2023-05-24T21:33:14Z   \n",
       "43868  50107528  2023-07-16T04:20:30Z   \n",
       "43869  50107528  2023-05-09T18:27:59Z   \n",
       "43870  50107528  2023-03-05T21:48:09Z   \n",
       "43871  50107528  2023-10-23T13:20:31Z   \n",
       "\n",
       "                                             review_text  review_rating  \n",
       "0      These Guys are really professional. Well behav...              5  \n",
       "1      I haven't had Dunkin Donuts in years. Being th...              1  \n",
       "2      This Dunkin is nice, but it's located inside a...              5  \n",
       "3      Ordered a box of joes they tried to cheat with...              2  \n",
       "4      Another review  my daughter and friends  love ...              4  \n",
       "...                                                  ...            ...  \n",
       "43867  Easy to locate, great customer service. Went i...              2  \n",
       "43868  A solid doner kebab. Good cuts of lamb and ple...              4  \n",
       "43869  We spent 5 days in NYC eating a lot of great (...              5  \n",
       "43870  Extremely authentic. Staff/owner is from Turke...              5  \n",
       "43871  The chicken is very tender, fresh Turkish brea...              5  \n",
       "\n",
       "[43872 rows x 4 columns]"
      ]
     },
     "execution_count": 4,
     "metadata": {},
     "output_type": "execute_result"
    }
   ],
   "source": [
    "def clean_api_reviews(api_data):\n",
    "    df = api_data.copy()\n",
    "    cols = ['camis', 'publish_time', 'review_text', 'review_rating']\n",
    "    df = df[cols]\n",
    "    return df\n",
    "\n",
    "clean_api_reviews(api_reviews)"
   ]
  },
  {
   "cell_type": "code",
   "execution_count": 5,
   "id": "6d70408b-448b-4969-81d7-0b3e553cf5bd",
   "metadata": {},
   "outputs": [],
   "source": [
    "def clean_dates(data):\n",
    "    scrape_reviews = data.copy()\n",
    "    scrape_reviews.relative_date = scrape_reviews.relative_date.apply(lambda x: x[:-4])\n",
    "    scrape_reviews.relative_date = ['1 years' if date == 'a year' else date for date in scrape_reviews.relative_date]\n",
    "    scrape_reviews.relative_date = [re.sub(r'^a', '1', date) if date[0] == 'a' else date for date in scrape_reviews.relative_date]\n",
    "    return scrape_reviews"
   ]
  },
  {
   "cell_type": "code",
   "execution_count": 6,
   "id": "74ffce42-e181-4b73-bad0-c35a3a2c0bfd",
   "metadata": {},
   "outputs": [],
   "source": [
    "reviews = clean_dates(scrape_reviews)"
   ]
  },
  {
   "cell_type": "code",
   "execution_count": 7,
   "id": "e0175231-27df-4d9c-8a10-ccfb1d66f190",
   "metadata": {},
   "outputs": [],
   "source": [
    "def adjust_dates(scrape_reviews):\n",
    "    \n",
    "    dataframes = []  # Create empty list to store dataframes\n",
    "    \n",
    "    # Isolate each restaurant by id\n",
    "    for restaurant_id in scrape_reviews.id.unique():\n",
    "        # Create dataframe of ONE restaurant\n",
    "        restaurant = scrape_reviews[scrape_reviews.id == restaurant_id].copy()\n",
    "        \n",
    "        # Create df of review counts per relative_date and calculate average distribution of reviews\n",
    "        place = scrape_reviews[scrape_reviews.id == restaurant_id]\n",
    "        review_counts = pd.DataFrame(place.relative_date.value_counts())\n",
    "        review_counts['increment'] = 365/review_counts.relative_date\n",
    "        \n",
    "        # Create empty list for new dates, i variable to count increments, and previous_year to track year \n",
    "        new_dates = []\n",
    "        i = 0\n",
    "        previous_year = '1 years'\n",
    "\n",
    "        for date in restaurant.relative_date: \n",
    "            if 'years' in date:  # If date is in years, function will adjust it to estimated date\n",
    "                if date != previous_year:  # When date changes from 'x years' to 'x + 1 years' counters are reset \n",
    "                    i = 0\n",
    "                    previous_year = date\n",
    "                # Calculate adjusted date\n",
    "                adjusted_date = (365*(int(re.findall(r'\\d+', date)[0]))) + (review_counts.loc[date].increment * i)\n",
    "                i += 1\n",
    "                new_dates.append(str(round(adjusted_date)))  # Append adjsuted date\n",
    "            else:\n",
    "                new_dates.append(date)  # Append normal date if date < 1 year\n",
    "        restaurant['new_date'] = new_dates  # Replace dates with new_dates\n",
    "        dataframes.append(restaurant)  # Append dataframe to list of dataframes\n",
    "    reviews = pd.concat(dataframes)  # Join all dataframes\n",
    "    return reviews  # Return joined data\n"
   ]
  },
  {
   "cell_type": "code",
   "execution_count": 8,
   "id": "92c80f60-468a-4af4-abeb-8a5b9cc7922c",
   "metadata": {},
   "outputs": [],
   "source": [
    "s = pd.read_csv('scraped_reviews.csv')"
   ]
  },
  {
   "cell_type": "code",
   "execution_count": 9,
   "id": "55b33bca-bfea-474c-8e1c-b175e57b0e18",
   "metadata": {},
   "outputs": [
    {
     "data": {
      "text/html": [
       "<div>\n",
       "<style scoped>\n",
       "    .dataframe tbody tr th:only-of-type {\n",
       "        vertical-align: middle;\n",
       "    }\n",
       "\n",
       "    .dataframe tbody tr th {\n",
       "        vertical-align: top;\n",
       "    }\n",
       "\n",
       "    .dataframe thead th {\n",
       "        text-align: right;\n",
       "    }\n",
       "</style>\n",
       "<table border=\"1\" class=\"dataframe\">\n",
       "  <thead>\n",
       "    <tr style=\"text-align: right;\">\n",
       "      <th></th>\n",
       "      <th>relative_date</th>\n",
       "    </tr>\n",
       "  </thead>\n",
       "  <tbody>\n",
       "    <tr>\n",
       "      <th>2 months ago</th>\n",
       "      <td>75</td>\n",
       "    </tr>\n",
       "    <tr>\n",
       "      <th>a month ago</th>\n",
       "      <td>49</td>\n",
       "    </tr>\n",
       "    <tr>\n",
       "      <th>2 weeks ago</th>\n",
       "      <td>20</td>\n",
       "    </tr>\n",
       "    <tr>\n",
       "      <th>a week ago</th>\n",
       "      <td>15</td>\n",
       "    </tr>\n",
       "    <tr>\n",
       "      <th>3 weeks ago</th>\n",
       "      <td>15</td>\n",
       "    </tr>\n",
       "    <tr>\n",
       "      <th>3 months ago</th>\n",
       "      <td>9</td>\n",
       "    </tr>\n",
       "    <tr>\n",
       "      <th>5 days ago</th>\n",
       "      <td>6</td>\n",
       "    </tr>\n",
       "    <tr>\n",
       "      <th>4 days ago</th>\n",
       "      <td>3</td>\n",
       "    </tr>\n",
       "    <tr>\n",
       "      <th>4 weeks ago</th>\n",
       "      <td>3</td>\n",
       "    </tr>\n",
       "    <tr>\n",
       "      <th>a day ago</th>\n",
       "      <td>2</td>\n",
       "    </tr>\n",
       "    <tr>\n",
       "      <th>6 days ago</th>\n",
       "      <td>2</td>\n",
       "    </tr>\n",
       "    <tr>\n",
       "      <th>11 hours ago</th>\n",
       "      <td>1</td>\n",
       "    </tr>\n",
       "  </tbody>\n",
       "</table>\n",
       "</div>"
      ],
      "text/plain": [
       "              relative_date\n",
       "2 months ago             75\n",
       "a month ago              49\n",
       "2 weeks ago              20\n",
       "a week ago               15\n",
       "3 weeks ago              15\n",
       "3 months ago              9\n",
       "5 days ago                6\n",
       "4 days ago                3\n",
       "4 weeks ago               3\n",
       "a day ago                 2\n",
       "6 days ago                2\n",
       "11 hours ago              1"
      ]
     },
     "execution_count": 9,
     "metadata": {},
     "output_type": "execute_result"
    }
   ],
   "source": [
    "place = s[s.id == 41375676]\n",
    "review_counts = pd.DataFrame(place.relative_date.value_counts())\n",
    "#review_counts.rename(columns={review_counts.columns[0]:'new_name'})\n",
    "# review_counts['increment'] = 365 / review_counts.index\n",
    "review_counts"
   ]
  },
  {
   "cell_type": "code",
   "execution_count": 10,
   "id": "fb35303d-4c94-4436-97d6-b74610cbb940",
   "metadata": {},
   "outputs": [],
   "source": [
    "reviews = adjust_dates(reviews)"
   ]
  },
  {
   "cell_type": "code",
   "execution_count": 11,
   "id": "2fd61031-2b00-4e22-873f-c4cf8ea05995",
   "metadata": {},
   "outputs": [],
   "source": [
    "def calculate_days(data):\n",
    "    reviews = data.copy()\n",
    "    new_date = []\n",
    "    for date in reviews.new_date:\n",
    "        #print(date)\n",
    "        unit = re.sub(r'[^a-z]', '', date)\n",
    "        if 'hour' in unit:\n",
    "            new_date.append('1')\n",
    "        elif 'day' in unit:\n",
    "            new_date.append(re.sub(r'[^0-9]', '', date))\n",
    "        elif 'week' in unit:\n",
    "            new_date.append(int(re.sub(r'[^0-9]', '', date))*7)\n",
    "        elif 'month' in unit:\n",
    "            new_date.append(int(re.sub(r'[^0-9]', '', date))*30)\n",
    "        else:\n",
    "            new_date.append(date)\n",
    "\n",
    "    reviews['newer_dates'] = new_date\n",
    "    reviews['final_date'] = [pd.to_datetime(retrieval_date) - timedelta(days = n) for retrieval_date,n in zip(reviews.retrieval_date, reviews.newer_dates.astype(int))]\n",
    "    return reviews"
   ]
  },
  {
   "cell_type": "code",
   "execution_count": 12,
   "id": "6d8ae918-8074-484c-ab0f-06cb1f2ae207",
   "metadata": {},
   "outputs": [],
   "source": [
    "final_df = calculate_days(reviews)"
   ]
  },
  {
   "cell_type": "code",
   "execution_count": 13,
   "id": "e1d880f4-4322-4ee9-a762-0b1ccca1ae00",
   "metadata": {},
   "outputs": [],
   "source": [
    "def clean_reviews(data):\n",
    "    final_df = data.copy()\n",
    "    cols = ['id', 'final_date', 'caption', 'rating']\n",
    "    final_df = final_df[cols]\n",
    "    final_df.rating = final_df.rating.astype(int)\n",
    "    final_df.columns = ['camis', 'publish_time', 'review_text', 'review_rating']\n",
    "    return final_df"
   ]
  },
  {
   "cell_type": "code",
   "execution_count": 14,
   "id": "a8afadf7-932e-4e38-ae4d-b6fe6dd34abb",
   "metadata": {},
   "outputs": [],
   "source": [
    "final_df = clean_reviews(final_df)"
   ]
  },
  {
   "cell_type": "code",
   "execution_count": 15,
   "id": "4a01ec89-4f4d-43a5-8b3e-246af1edafd1",
   "metadata": {},
   "outputs": [
    {
     "data": {
      "text/html": [
       "<div>\n",
       "<style scoped>\n",
       "    .dataframe tbody tr th:only-of-type {\n",
       "        vertical-align: middle;\n",
       "    }\n",
       "\n",
       "    .dataframe tbody tr th {\n",
       "        vertical-align: top;\n",
       "    }\n",
       "\n",
       "    .dataframe thead th {\n",
       "        text-align: right;\n",
       "    }\n",
       "</style>\n",
       "<table border=\"1\" class=\"dataframe\">\n",
       "  <thead>\n",
       "    <tr style=\"text-align: right;\">\n",
       "      <th></th>\n",
       "      <th>camis</th>\n",
       "      <th>publish_time</th>\n",
       "      <th>review_text</th>\n",
       "      <th>review_rating</th>\n",
       "    </tr>\n",
       "  </thead>\n",
       "  <tbody>\n",
       "    <tr>\n",
       "      <th>0</th>\n",
       "      <td>41375676</td>\n",
       "      <td>2023-11-01 02:44:04.226505</td>\n",
       "      <td>NaN</td>\n",
       "      <td>5</td>\n",
       "    </tr>\n",
       "    <tr>\n",
       "      <th>1</th>\n",
       "      <td>41375676</td>\n",
       "      <td>2023-11-01 02:44:04.227451</td>\n",
       "      <td>NaN</td>\n",
       "      <td>5</td>\n",
       "    </tr>\n",
       "    <tr>\n",
       "      <th>2</th>\n",
       "      <td>41375676</td>\n",
       "      <td>2023-11-01 02:44:04.227954</td>\n",
       "      <td>NaN</td>\n",
       "      <td>5</td>\n",
       "    </tr>\n",
       "    <tr>\n",
       "      <th>3</th>\n",
       "      <td>41375676</td>\n",
       "      <td>2023-10-29 02:44:04.228882</td>\n",
       "      <td>Fabulous food</td>\n",
       "      <td>5</td>\n",
       "    </tr>\n",
       "    <tr>\n",
       "      <th>4</th>\n",
       "      <td>41375676</td>\n",
       "      <td>2023-10-29 02:44:04.229576</td>\n",
       "      <td>Overrated.  Terrible service, the fault of the...</td>\n",
       "      <td>3</td>\n",
       "    </tr>\n",
       "  </tbody>\n",
       "</table>\n",
       "</div>"
      ],
      "text/plain": [
       "      camis               publish_time  \\\n",
       "0  41375676 2023-11-01 02:44:04.226505   \n",
       "1  41375676 2023-11-01 02:44:04.227451   \n",
       "2  41375676 2023-11-01 02:44:04.227954   \n",
       "3  41375676 2023-10-29 02:44:04.228882   \n",
       "4  41375676 2023-10-29 02:44:04.229576   \n",
       "\n",
       "                                         review_text  review_rating  \n",
       "0                                                NaN              5  \n",
       "1                                                NaN              5  \n",
       "2                                                NaN              5  \n",
       "3                                      Fabulous food              5  \n",
       "4  Overrated.  Terrible service, the fault of the...              3  "
      ]
     },
     "execution_count": 15,
     "metadata": {},
     "output_type": "execute_result"
    }
   ],
   "source": [
    "final_df.head()"
   ]
  },
  {
   "cell_type": "code",
   "execution_count": 16,
   "id": "061455e9-a2f4-40c5-a618-8aeecba905c8",
   "metadata": {},
   "outputs": [],
   "source": [
    "api_reviews = pd.read_csv('reviews_progress.csv')\n",
    "scrape_reviews = pd.read_csv('scraped_reviews.csv')"
   ]
  },
  {
   "cell_type": "code",
   "execution_count": 17,
   "id": "9acbd008-1fd7-43a8-8a2e-9270373a5b17",
   "metadata": {},
   "outputs": [
    {
     "data": {
      "text/html": [
       "<div>\n",
       "<style scoped>\n",
       "    .dataframe tbody tr th:only-of-type {\n",
       "        vertical-align: middle;\n",
       "    }\n",
       "\n",
       "    .dataframe tbody tr th {\n",
       "        vertical-align: top;\n",
       "    }\n",
       "\n",
       "    .dataframe thead th {\n",
       "        text-align: right;\n",
       "    }\n",
       "</style>\n",
       "<table border=\"1\" class=\"dataframe\">\n",
       "  <thead>\n",
       "    <tr style=\"text-align: right;\">\n",
       "      <th></th>\n",
       "      <th>camis</th>\n",
       "      <th>publish_time</th>\n",
       "      <th>review_text</th>\n",
       "      <th>review_rating</th>\n",
       "    </tr>\n",
       "  </thead>\n",
       "  <tbody>\n",
       "    <tr>\n",
       "      <th>0</th>\n",
       "      <td>41375676</td>\n",
       "      <td>2023-11-01 02:44:04.226505</td>\n",
       "      <td>NaN</td>\n",
       "      <td>5</td>\n",
       "    </tr>\n",
       "    <tr>\n",
       "      <th>1</th>\n",
       "      <td>41375676</td>\n",
       "      <td>2023-11-01 02:44:04.227451</td>\n",
       "      <td>NaN</td>\n",
       "      <td>5</td>\n",
       "    </tr>\n",
       "    <tr>\n",
       "      <th>2</th>\n",
       "      <td>41375676</td>\n",
       "      <td>2023-11-01 02:44:04.227954</td>\n",
       "      <td>NaN</td>\n",
       "      <td>5</td>\n",
       "    </tr>\n",
       "    <tr>\n",
       "      <th>3</th>\n",
       "      <td>41375676</td>\n",
       "      <td>2023-10-29 02:44:04.228882</td>\n",
       "      <td>Fabulous food</td>\n",
       "      <td>5</td>\n",
       "    </tr>\n",
       "    <tr>\n",
       "      <th>4</th>\n",
       "      <td>41375676</td>\n",
       "      <td>2023-10-29 02:44:04.229576</td>\n",
       "      <td>Overrated.  Terrible service, the fault of the...</td>\n",
       "      <td>3</td>\n",
       "    </tr>\n",
       "    <tr>\n",
       "      <th>...</th>\n",
       "      <td>...</td>\n",
       "      <td>...</td>\n",
       "      <td>...</td>\n",
       "      <td>...</td>\n",
       "    </tr>\n",
       "    <tr>\n",
       "      <th>43867</th>\n",
       "      <td>50107528</td>\n",
       "      <td>2023-05-24 21:33:14+00:00</td>\n",
       "      <td>Easy to locate, great customer service. Went i...</td>\n",
       "      <td>2</td>\n",
       "    </tr>\n",
       "    <tr>\n",
       "      <th>43868</th>\n",
       "      <td>50107528</td>\n",
       "      <td>2023-07-16 04:20:30+00:00</td>\n",
       "      <td>A solid doner kebab. Good cuts of lamb and ple...</td>\n",
       "      <td>4</td>\n",
       "    </tr>\n",
       "    <tr>\n",
       "      <th>43869</th>\n",
       "      <td>50107528</td>\n",
       "      <td>2023-05-09 18:27:59+00:00</td>\n",
       "      <td>We spent 5 days in NYC eating a lot of great (...</td>\n",
       "      <td>5</td>\n",
       "    </tr>\n",
       "    <tr>\n",
       "      <th>43870</th>\n",
       "      <td>50107528</td>\n",
       "      <td>2023-03-05 21:48:09+00:00</td>\n",
       "      <td>Extremely authentic. Staff/owner is from Turke...</td>\n",
       "      <td>5</td>\n",
       "    </tr>\n",
       "    <tr>\n",
       "      <th>43871</th>\n",
       "      <td>50107528</td>\n",
       "      <td>2023-10-23 13:20:31+00:00</td>\n",
       "      <td>The chicken is very tender, fresh Turkish brea...</td>\n",
       "      <td>5</td>\n",
       "    </tr>\n",
       "  </tbody>\n",
       "</table>\n",
       "<p>61337 rows × 4 columns</p>\n",
       "</div>"
      ],
      "text/plain": [
       "          camis                publish_time  \\\n",
       "0      41375676  2023-11-01 02:44:04.226505   \n",
       "1      41375676  2023-11-01 02:44:04.227451   \n",
       "2      41375676  2023-11-01 02:44:04.227954   \n",
       "3      41375676  2023-10-29 02:44:04.228882   \n",
       "4      41375676  2023-10-29 02:44:04.229576   \n",
       "...         ...                         ...   \n",
       "43867  50107528   2023-05-24 21:33:14+00:00   \n",
       "43868  50107528   2023-07-16 04:20:30+00:00   \n",
       "43869  50107528   2023-05-09 18:27:59+00:00   \n",
       "43870  50107528   2023-03-05 21:48:09+00:00   \n",
       "43871  50107528   2023-10-23 13:20:31+00:00   \n",
       "\n",
       "                                             review_text  review_rating  \n",
       "0                                                    NaN              5  \n",
       "1                                                    NaN              5  \n",
       "2                                                    NaN              5  \n",
       "3                                          Fabulous food              5  \n",
       "4      Overrated.  Terrible service, the fault of the...              3  \n",
       "...                                                  ...            ...  \n",
       "43867  Easy to locate, great customer service. Went i...              2  \n",
       "43868  A solid doner kebab. Good cuts of lamb and ple...              4  \n",
       "43869  We spent 5 days in NYC eating a lot of great (...              5  \n",
       "43870  Extremely authentic. Staff/owner is from Turke...              5  \n",
       "43871  The chicken is very tender, fresh Turkish brea...              5  \n",
       "\n",
       "[61337 rows x 4 columns]"
      ]
     },
     "execution_count": 17,
     "metadata": {},
     "output_type": "execute_result"
    }
   ],
   "source": [
    "prep.cleanse_reviews(scrape_reviews, api_reviews)"
   ]
  },
  {
   "cell_type": "code",
   "execution_count": 18,
   "id": "bc51ffd9-82c1-4957-b899-3537f983138b",
   "metadata": {},
   "outputs": [],
   "source": [
    "r = pd.read_csv('reviews.csv')"
   ]
  },
  {
   "cell_type": "code",
   "execution_count": 19,
   "id": "bfe85bd4-7afa-45ab-bab4-46b6ee1fca00",
   "metadata": {},
   "outputs": [
    {
     "data": {
      "text/plain": [
       "0        2023-11-01 02:44:04.226505\n",
       "1        2023-11-01 02:44:04.227451\n",
       "2        2023-11-01 02:44:04.227954\n",
       "3        2023-10-29 02:44:04.228882\n",
       "4        2023-10-29 02:44:04.229576\n",
       "                    ...            \n",
       "61332     2023-05-24 21:33:14+00:00\n",
       "61333     2023-07-16 04:20:30+00:00\n",
       "61334     2023-05-09 18:27:59+00:00\n",
       "61335     2023-03-05 21:48:09+00:00\n",
       "61336     2023-10-23 13:20:31+00:00\n",
       "Name: publish_time, Length: 61337, dtype: object"
      ]
     },
     "execution_count": 19,
     "metadata": {},
     "output_type": "execute_result"
    }
   ],
   "source": [
    "pd.to_datetime(r.publish_time)"
   ]
  },
  {
   "cell_type": "code",
   "execution_count": 21,
   "id": "ca3cd881-0b1e-47de-9899-a79d58ee6507",
   "metadata": {},
   "outputs": [
    {
     "name": "stderr",
     "output_type": "stream",
     "text": [
      "[autoreload of tornado.locks failed: Traceback (most recent call last):\n",
      "  File \"/opt/homebrew/anaconda3/lib/python3.10/site-packages/IPython/extensions/autoreload.py\", line 261, in check\n",
      "  File \"/opt/homebrew/anaconda3/lib/python3.10/site-packages/IPython/extensions/autoreload.py\", line 484, in superreload\n",
      "  File \"/opt/homebrew/anaconda3/lib/python3.10/site-packages/IPython/extensions/autoreload.py\", line 381, in update_generic\n",
      "  File \"/opt/homebrew/anaconda3/lib/python3.10/site-packages/IPython/extensions/autoreload.py\", line 333, in update_class\n",
      "  File \"/opt/homebrew/anaconda3/lib/python3.10/site-packages/IPython/extensions/autoreload.py\", line 381, in update_generic\n",
      "  File \"/opt/homebrew/anaconda3/lib/python3.10/site-packages/IPython/extensions/autoreload.py\", line 293, in update_function\n",
      "ValueError: __init__() requires a code object with 1 free vars, not 0\n",
      "]\n",
      "[autoreload of numpy.core.overrides failed: Traceback (most recent call last):\n",
      "  File \"/opt/homebrew/anaconda3/lib/python3.10/site-packages/IPython/extensions/autoreload.py\", line 261, in check\n",
      "  File \"/opt/homebrew/anaconda3/lib/python3.10/site-packages/IPython/extensions/autoreload.py\", line 459, in superreload\n",
      "  File \"/opt/homebrew/anaconda3/lib/python3.10/importlib/__init__.py\", line 169, in reload\n",
      "    _bootstrap._exec(spec, module)\n",
      "  File \"<frozen importlib._bootstrap>\", line 619, in _exec\n",
      "  File \"<frozen importlib._bootstrap_external>\", line 883, in exec_module\n",
      "  File \"<frozen importlib._bootstrap>\", line 241, in _call_with_frames_removed\n",
      "  File \"/opt/homebrew/anaconda3/lib/python3.10/site-packages/numpy/core/overrides.py\", line 8, in <module>\n",
      "    from numpy.core._multiarray_umath import (\n",
      "ImportError: cannot import name '_ArrayFunctionDispatcher' from 'numpy.core._multiarray_umath' (/opt/homebrew/anaconda3/lib/python3.10/site-packages/numpy/core/_multiarray_umath.cpython-310-darwin.so)\n",
      "]\n",
      "[autoreload of numpy.core.multiarray failed: Traceback (most recent call last):\n",
      "  File \"/opt/homebrew/anaconda3/lib/python3.10/site-packages/IPython/extensions/autoreload.py\", line 261, in check\n",
      "  File \"/opt/homebrew/anaconda3/lib/python3.10/site-packages/IPython/extensions/autoreload.py\", line 459, in superreload\n",
      "  File \"/opt/homebrew/anaconda3/lib/python3.10/importlib/__init__.py\", line 169, in reload\n",
      "    _bootstrap._exec(spec, module)\n",
      "  File \"<frozen importlib._bootstrap>\", line 619, in _exec\n",
      "  File \"<frozen importlib._bootstrap_external>\", line 883, in exec_module\n",
      "  File \"<frozen importlib._bootstrap>\", line 241, in _call_with_frames_removed\n",
      "  File \"/opt/homebrew/anaconda3/lib/python3.10/site-packages/numpy/core/multiarray.py\", line 16, in <module>\n",
      "    from ._multiarray_umath import (\n",
      "ImportError: cannot import name 'fastCopyAndTranspose' from 'numpy.core._multiarray_umath' (/opt/homebrew/anaconda3/lib/python3.10/site-packages/numpy/core/_multiarray_umath.cpython-310-darwin.so)\n",
      "]\n",
      "[autoreload of numpy.core._methods failed: Traceback (most recent call last):\n",
      "  File \"/opt/homebrew/anaconda3/lib/python3.10/site-packages/IPython/extensions/autoreload.py\", line 261, in check\n",
      "  File \"/opt/homebrew/anaconda3/lib/python3.10/site-packages/IPython/extensions/autoreload.py\", line 459, in superreload\n",
      "  File \"/opt/homebrew/anaconda3/lib/python3.10/importlib/__init__.py\", line 169, in reload\n",
      "    _bootstrap._exec(spec, module)\n",
      "  File \"<frozen importlib._bootstrap>\", line 619, in _exec\n",
      "  File \"<frozen importlib._bootstrap_external>\", line 883, in exec_module\n",
      "  File \"<frozen importlib._bootstrap>\", line 241, in _call_with_frames_removed\n",
      "  File \"/opt/homebrew/anaconda3/lib/python3.10/site-packages/numpy/core/_methods.py\", line 14, in <module>\n",
      "    from numpy.core._ufunc_config import _no_nep50_warning\n",
      "ImportError: cannot import name '_no_nep50_warning' from 'numpy.core._ufunc_config' (/opt/homebrew/anaconda3/lib/python3.10/site-packages/numpy/core/_ufunc_config.py)\n",
      "]\n",
      "[autoreload of numpy.core._asarray failed: Traceback (most recent call last):\n",
      "  File \"/opt/homebrew/anaconda3/lib/python3.10/site-packages/IPython/extensions/autoreload.py\", line 261, in check\n",
      "  File \"/opt/homebrew/anaconda3/lib/python3.10/site-packages/IPython/extensions/autoreload.py\", line 459, in superreload\n",
      "  File \"/opt/homebrew/anaconda3/lib/python3.10/importlib/__init__.py\", line 169, in reload\n",
      "    _bootstrap._exec(spec, module)\n",
      "  File \"<frozen importlib._bootstrap>\", line 619, in _exec\n",
      "  File \"<frozen importlib._bootstrap_external>\", line 883, in exec_module\n",
      "  File \"<frozen importlib._bootstrap>\", line 241, in _call_with_frames_removed\n",
      "  File \"/opt/homebrew/anaconda3/lib/python3.10/site-packages/numpy/core/_asarray.py\", line 134, in <module>\n",
      "    _require_with_like = array_function_dispatch()(require)\n",
      "TypeError: array_function_dispatch() missing 1 required positional argument: 'dispatcher'\n",
      "]\n",
      "[autoreload of numpy.core.numeric failed: Traceback (most recent call last):\n",
      "  File \"/opt/homebrew/anaconda3/lib/python3.10/site-packages/IPython/extensions/autoreload.py\", line 261, in check\n",
      "  File \"/opt/homebrew/anaconda3/lib/python3.10/site-packages/IPython/extensions/autoreload.py\", line 459, in superreload\n",
      "  File \"/opt/homebrew/anaconda3/lib/python3.10/importlib/__init__.py\", line 169, in reload\n",
      "    _bootstrap._exec(spec, module)\n",
      "  File \"<frozen importlib._bootstrap>\", line 619, in _exec\n",
      "  File \"<frozen importlib._bootstrap_external>\", line 883, in exec_module\n",
      "  File \"<frozen importlib._bootstrap>\", line 241, in _call_with_frames_removed\n",
      "  File \"/opt/homebrew/anaconda3/lib/python3.10/site-packages/numpy/core/numeric.py\", line 11, in <module>\n",
      "    from .multiarray import (\n",
      "ImportError: cannot import name 'fastCopyAndTranspose' from 'numpy.core.multiarray' (/opt/homebrew/anaconda3/lib/python3.10/site-packages/numpy/core/multiarray.py)\n",
      "]\n",
      "[autoreload of numpy.core._add_newdocs failed: Traceback (most recent call last):\n",
      "  File \"/opt/homebrew/anaconda3/lib/python3.10/site-packages/IPython/extensions/autoreload.py\", line 261, in check\n",
      "  File \"/opt/homebrew/anaconda3/lib/python3.10/site-packages/IPython/extensions/autoreload.py\", line 459, in superreload\n",
      "  File \"/opt/homebrew/anaconda3/lib/python3.10/importlib/__init__.py\", line 169, in reload\n",
      "    _bootstrap._exec(spec, module)\n",
      "  File \"<frozen importlib._bootstrap>\", line 619, in _exec\n",
      "  File \"<frozen importlib._bootstrap_external>\", line 883, in exec_module\n",
      "  File \"<frozen importlib._bootstrap>\", line 241, in _call_with_frames_removed\n",
      "  File \"/opt/homebrew/anaconda3/lib/python3.10/site-packages/numpy/core/_add_newdocs.py\", line 5700, in <module>\n",
      "    add_newdoc('numpy.core', 'ufunc', ('resolve_dtypes',\n",
      "  File \"/opt/homebrew/anaconda3/lib/python3.10/site-packages/numpy/core/function_base.py\", line 548, in add_newdoc\n",
      "    _add_docstring(getattr(new, attr), docstring.strip(), warn_on_python)\n",
      "AttributeError: type object 'numpy.ufunc' has no attribute 'resolve_dtypes'\n",
      "]\n",
      "[autoreload of numpy.lib.ufunclike failed: Traceback (most recent call last):\n",
      "  File \"/opt/homebrew/anaconda3/lib/python3.10/site-packages/IPython/extensions/autoreload.py\", line 261, in check\n",
      "  File \"/opt/homebrew/anaconda3/lib/python3.10/site-packages/IPython/extensions/autoreload.py\", line 484, in superreload\n",
      "  File \"/opt/homebrew/anaconda3/lib/python3.10/site-packages/IPython/extensions/autoreload.py\", line 381, in update_generic\n",
      "  File \"/opt/homebrew/anaconda3/lib/python3.10/site-packages/IPython/extensions/autoreload.py\", line 293, in update_function\n",
      "ValueError: _dispatcher() requires a code object with 1 free vars, not 0\n",
      "]\n",
      "[autoreload of numpy.lib.twodim_base failed: Traceback (most recent call last):\n",
      "  File \"/opt/homebrew/anaconda3/lib/python3.10/site-packages/IPython/extensions/autoreload.py\", line 261, in check\n",
      "  File \"/opt/homebrew/anaconda3/lib/python3.10/site-packages/IPython/extensions/autoreload.py\", line 459, in superreload\n",
      "  File \"/opt/homebrew/anaconda3/lib/python3.10/importlib/__init__.py\", line 169, in reload\n",
      "    _bootstrap._exec(spec, module)\n",
      "  File \"<frozen importlib._bootstrap>\", line 619, in _exec\n",
      "  File \"<frozen importlib._bootstrap_external>\", line 883, in exec_module\n",
      "  File \"<frozen importlib._bootstrap>\", line 241, in _call_with_frames_removed\n",
      "  File \"/opt/homebrew/anaconda3/lib/python3.10/site-packages/numpy/lib/twodim_base.py\", line 227, in <module>\n",
      "    _eye_with_like = array_function_dispatch()(eye)\n",
      "TypeError: array_function_dispatch() missing 1 required positional argument: 'dispatcher'\n",
      "]\n",
      "[autoreload of numpy.linalg.linalg failed: Traceback (most recent call last):\n",
      "  File \"/opt/homebrew/anaconda3/lib/python3.10/site-packages/IPython/extensions/autoreload.py\", line 261, in check\n",
      "  File \"/opt/homebrew/anaconda3/lib/python3.10/site-packages/IPython/extensions/autoreload.py\", line 459, in superreload\n",
      "  File \"/opt/homebrew/anaconda3/lib/python3.10/importlib/__init__.py\", line 169, in reload\n",
      "    _bootstrap._exec(spec, module)\n",
      "  File \"<frozen importlib._bootstrap>\", line 619, in _exec\n",
      "  File \"<frozen importlib._bootstrap_external>\", line 883, in exec_module\n",
      "  File \"<frozen importlib._bootstrap>\", line 241, in _call_with_frames_removed\n",
      "  File \"/opt/homebrew/anaconda3/lib/python3.10/site-packages/numpy/linalg/linalg.py\", line 108, in <module>\n",
      "    _linalg_error_extobj = _determine_error_states()\n",
      "  File \"/opt/homebrew/anaconda3/lib/python3.10/site-packages/numpy/linalg/linalg.py\", line 101, in _determine_error_states\n",
      "    with errstate(invalid='call', over='ignore',\n",
      "  File \"/opt/homebrew/anaconda3/lib/python3.10/site-packages/numpy/core/_ufunc_config.py\", line 432, in __enter__\n",
      "    if self.call is not _Unspecified:\n",
      "  File \"/opt/homebrew/anaconda3/lib/python3.10/site-packages/numpy/core/_ufunc_config.py\", line 306, in seterrcall\n",
      "    raise ValueError(\"Only callable can be used as callback\")\n",
      "ValueError: Only callable can be used as callback\n",
      "]\n",
      "[autoreload of numpy.lib.function_base failed: Traceback (most recent call last):\n",
      "  File \"/opt/homebrew/anaconda3/lib/python3.10/site-packages/IPython/extensions/autoreload.py\", line 261, in check\n",
      "  File \"/opt/homebrew/anaconda3/lib/python3.10/site-packages/IPython/extensions/autoreload.py\", line 459, in superreload\n",
      "  File \"/opt/homebrew/anaconda3/lib/python3.10/importlib/__init__.py\", line 169, in reload\n",
      "    _bootstrap._exec(spec, module)\n",
      "  File \"<frozen importlib._bootstrap>\", line 619, in _exec\n",
      "  File \"<frozen importlib._bootstrap_external>\", line 883, in exec_module\n",
      "  File \"<frozen importlib._bootstrap>\", line 241, in _call_with_frames_removed\n",
      "  File \"/opt/homebrew/anaconda3/lib/python3.10/site-packages/numpy/lib/function_base.py\", line 26, in <module>\n",
      "    from numpy.core.multiarray import (\n",
      "ImportError: cannot import name '_place' from 'numpy.core.multiarray' (/opt/homebrew/anaconda3/lib/python3.10/site-packages/numpy/core/multiarray.py)\n",
      "]\n",
      "[autoreload of numpy.lib.npyio failed: Traceback (most recent call last):\n",
      "  File \"/opt/homebrew/anaconda3/lib/python3.10/site-packages/IPython/extensions/autoreload.py\", line 261, in check\n",
      "  File \"/opt/homebrew/anaconda3/lib/python3.10/site-packages/IPython/extensions/autoreload.py\", line 459, in superreload\n",
      "  File \"/opt/homebrew/anaconda3/lib/python3.10/importlib/__init__.py\", line 169, in reload\n",
      "    _bootstrap._exec(spec, module)\n",
      "  File \"<frozen importlib._bootstrap>\", line 619, in _exec\n",
      "  File \"<frozen importlib._bootstrap_external>\", line 883, in exec_module\n",
      "  File \"<frozen importlib._bootstrap>\", line 241, in _call_with_frames_removed\n",
      "  File \"/opt/homebrew/anaconda3/lib/python3.10/site-packages/numpy/lib/npyio.py\", line 1381, in <module>\n",
      "    _loadtxt_with_like = array_function_dispatch()(loadtxt)\n",
      "TypeError: array_function_dispatch() missing 1 required positional argument: 'dispatcher'\n",
      "]\n",
      "[autoreload of numpy.ma.core failed: Traceback (most recent call last):\n",
      "  File \"/opt/homebrew/anaconda3/lib/python3.10/site-packages/IPython/extensions/autoreload.py\", line 261, in check\n",
      "  File \"/opt/homebrew/anaconda3/lib/python3.10/site-packages/IPython/extensions/autoreload.py\", line 484, in superreload\n",
      "  File \"/opt/homebrew/anaconda3/lib/python3.10/site-packages/IPython/extensions/autoreload.py\", line 381, in update_generic\n",
      "  File \"/opt/homebrew/anaconda3/lib/python3.10/site-packages/IPython/extensions/autoreload.py\", line 333, in update_class\n",
      "  File \"/opt/homebrew/anaconda3/lib/python3.10/site-packages/IPython/extensions/autoreload.py\", line 381, in update_generic\n",
      "  File \"/opt/homebrew/anaconda3/lib/python3.10/site-packages/IPython/extensions/autoreload.py\", line 293, in update_function\n",
      "ValueError: __setitem__() requires a code object with 0 free vars, not 2\n",
      "]\n",
      "[autoreload of numpy failed: Traceback (most recent call last):\n",
      "  File \"/opt/homebrew/anaconda3/lib/python3.10/site-packages/IPython/extensions/autoreload.py\", line 261, in check\n",
      "  File \"/opt/homebrew/anaconda3/lib/python3.10/site-packages/IPython/extensions/autoreload.py\", line 459, in superreload\n",
      "  File \"/opt/homebrew/anaconda3/lib/python3.10/importlib/__init__.py\", line 169, in reload\n",
      "    _bootstrap._exec(spec, module)\n",
      "  File \"<frozen importlib._bootstrap>\", line 619, in _exec\n",
      "  File \"<frozen importlib._bootstrap_external>\", line 883, in exec_module\n",
      "  File \"<frozen importlib._bootstrap>\", line 241, in _call_with_frames_removed\n",
      "  File \"/opt/homebrew/anaconda3/lib/python3.10/site-packages/numpy/__init__.py\", line 235, in <module>\n",
      "    core.getlimits._register_known_types()\n",
      "  File \"/opt/homebrew/anaconda3/lib/python3.10/site-packages/numpy/core/getlimits.py\", line 228, in _register_known_types\n",
      "    with numeric.errstate(all='ignore'):\n",
      "  File \"/opt/homebrew/anaconda3/lib/python3.10/site-packages/numpy/core/_ufunc_config.py\", line 432, in __enter__\n",
      "    if self.call is not _Unspecified:\n",
      "  File \"/opt/homebrew/anaconda3/lib/python3.10/site-packages/numpy/core/_ufunc_config.py\", line 306, in seterrcall\n",
      "    raise ValueError(\"Only callable can be used as callback\")\n",
      "ValueError: Only callable can be used as callback\n",
      "]\n",
      "[autoreload of pandas._libs.tslibs failed: Traceback (most recent call last):\n",
      "  File \"/opt/homebrew/anaconda3/lib/python3.10/site-packages/IPython/extensions/autoreload.py\", line 261, in check\n",
      "  File \"/opt/homebrew/anaconda3/lib/python3.10/site-packages/IPython/extensions/autoreload.py\", line 459, in superreload\n",
      "  File \"/opt/homebrew/anaconda3/lib/python3.10/importlib/__init__.py\", line 169, in reload\n",
      "    _bootstrap._exec(spec, module)\n",
      "  File \"<frozen importlib._bootstrap>\", line 619, in _exec\n",
      "  File \"<frozen importlib._bootstrap_external>\", line 883, in exec_module\n",
      "  File \"<frozen importlib._bootstrap>\", line 241, in _call_with_frames_removed\n",
      "  File \"/opt/homebrew/anaconda3/lib/python3.10/site-packages/pandas/_libs/tslibs/__init__.py\", line 40, in <module>\n",
      "    from pandas._libs.tslibs.dtypes import (\n",
      "ImportError: cannot import name 'get_supported_reso' from 'pandas._libs.tslibs.dtypes' (/opt/homebrew/anaconda3/lib/python3.10/site-packages/pandas/_libs/tslibs/dtypes.cpython-310-darwin.so)\n",
      "]\n",
      "[autoreload of pandas.core.dtypes.dtypes failed: Traceback (most recent call last):\n",
      "  File \"/opt/homebrew/anaconda3/lib/python3.10/site-packages/IPython/extensions/autoreload.py\", line 261, in check\n",
      "  File \"/opt/homebrew/anaconda3/lib/python3.10/site-packages/IPython/extensions/autoreload.py\", line 459, in superreload\n",
      "  File \"/opt/homebrew/anaconda3/lib/python3.10/importlib/__init__.py\", line 169, in reload\n",
      "    _bootstrap._exec(spec, module)\n",
      "  File \"<frozen importlib._bootstrap>\", line 619, in _exec\n",
      "  File \"<frozen importlib._bootstrap_external>\", line 883, in exec_module\n",
      "  File \"<frozen importlib._bootstrap>\", line 241, in _call_with_frames_removed\n",
      "  File \"/opt/homebrew/anaconda3/lib/python3.10/site-packages/pandas/core/dtypes/dtypes.py\", line 41, in <module>\n",
      "    from pandas._libs.tslibs.dtypes import (\n",
      "ImportError: cannot import name 'abbrev_to_npy_unit' from 'pandas._libs.tslibs.dtypes' (/opt/homebrew/anaconda3/lib/python3.10/site-packages/pandas/_libs/tslibs/dtypes.cpython-310-darwin.so)\n",
      "]\n",
      "[autoreload of pandas.core.dtypes.common failed: Traceback (most recent call last):\n",
      "  File \"/opt/homebrew/anaconda3/lib/python3.10/site-packages/IPython/extensions/autoreload.py\", line 261, in check\n",
      "  File \"/opt/homebrew/anaconda3/lib/python3.10/site-packages/IPython/extensions/autoreload.py\", line 459, in superreload\n",
      "  File \"/opt/homebrew/anaconda3/lib/python3.10/importlib/__init__.py\", line 169, in reload\n",
      "    _bootstrap._exec(spec, module)\n",
      "  File \"<frozen importlib._bootstrap>\", line 619, in _exec\n",
      "  File \"<frozen importlib._bootstrap_external>\", line 883, in exec_module\n",
      "  File \"<frozen importlib._bootstrap>\", line 241, in _call_with_frames_removed\n",
      "  File \"/opt/homebrew/anaconda3/lib/python3.10/site-packages/pandas/core/dtypes/common.py\", line 25, in <module>\n",
      "    from pandas.core.dtypes.dtypes import (\n",
      "ImportError: cannot import name 'SparseDtype' from 'pandas.core.dtypes.dtypes' (/opt/homebrew/anaconda3/lib/python3.10/site-packages/pandas/core/dtypes/dtypes.py)\n",
      "]\n",
      "[autoreload of pandas.core.dtypes.astype failed: Traceback (most recent call last):\n",
      "  File \"/opt/homebrew/anaconda3/lib/python3.10/site-packages/IPython/extensions/autoreload.py\", line 261, in check\n",
      "  File \"/opt/homebrew/anaconda3/lib/python3.10/site-packages/IPython/extensions/autoreload.py\", line 459, in superreload\n",
      "  File \"/opt/homebrew/anaconda3/lib/python3.10/importlib/__init__.py\", line 169, in reload\n",
      "    _bootstrap._exec(spec, module)\n",
      "  File \"<frozen importlib._bootstrap>\", line 619, in _exec\n",
      "  File \"<frozen importlib._bootstrap_external>\", line 883, in exec_module\n",
      "  File \"<frozen importlib._bootstrap>\", line 241, in _call_with_frames_removed\n",
      "  File \"/opt/homebrew/anaconda3/lib/python3.10/site-packages/pandas/core/dtypes/astype.py\", line 25, in <module>\n",
      "    from pandas.core.dtypes.dtypes import (\n",
      "ImportError: cannot import name 'NumpyEADtype' from 'pandas.core.dtypes.dtypes' (/opt/homebrew/anaconda3/lib/python3.10/site-packages/pandas/core/dtypes/dtypes.py)\n",
      "]\n",
      "[autoreload of pandas.core.dtypes.cast failed: Traceback (most recent call last):\n",
      "  File \"/opt/homebrew/anaconda3/lib/python3.10/site-packages/IPython/extensions/autoreload.py\", line 261, in check\n",
      "  File \"/opt/homebrew/anaconda3/lib/python3.10/site-packages/IPython/extensions/autoreload.py\", line 459, in superreload\n",
      "  File \"/opt/homebrew/anaconda3/lib/python3.10/importlib/__init__.py\", line 169, in reload\n",
      "    _bootstrap._exec(spec, module)\n",
      "  File \"<frozen importlib._bootstrap>\", line 619, in _exec\n",
      "  File \"<frozen importlib._bootstrap_external>\", line 883, in exec_module\n",
      "  File \"<frozen importlib._bootstrap>\", line 241, in _call_with_frames_removed\n",
      "  File \"/opt/homebrew/anaconda3/lib/python3.10/site-packages/pandas/core/dtypes/cast.py\", line 60, in <module>\n",
      "    from pandas.core.dtypes.dtypes import (\n",
      "ImportError: cannot import name 'ArrowDtype' from 'pandas.core.dtypes.dtypes' (/opt/homebrew/anaconda3/lib/python3.10/site-packages/pandas/core/dtypes/dtypes.py)\n",
      "]\n",
      "[autoreload of pandas.core.dtypes.concat failed: Traceback (most recent call last):\n",
      "  File \"/opt/homebrew/anaconda3/lib/python3.10/site-packages/IPython/extensions/autoreload.py\", line 261, in check\n",
      "  File \"/opt/homebrew/anaconda3/lib/python3.10/site-packages/IPython/extensions/autoreload.py\", line 459, in superreload\n",
      "  File \"/opt/homebrew/anaconda3/lib/python3.10/importlib/__init__.py\", line 169, in reload\n",
      "    _bootstrap._exec(spec, module)\n",
      "  File \"<frozen importlib._bootstrap>\", line 619, in _exec\n",
      "  File \"<frozen importlib._bootstrap_external>\", line 883, in exec_module\n",
      "  File \"<frozen importlib._bootstrap>\", line 241, in _call_with_frames_removed\n",
      "  File \"/opt/homebrew/anaconda3/lib/python3.10/site-packages/pandas/core/dtypes/concat.py\", line 18, in <module>\n",
      "    from pandas.core.dtypes.cast import (\n",
      "ImportError: cannot import name 'np_find_common_type' from 'pandas.core.dtypes.cast' (/opt/homebrew/anaconda3/lib/python3.10/site-packages/pandas/core/dtypes/cast.py)\n",
      "]\n",
      "[autoreload of pandas.core.construction failed: Traceback (most recent call last):\n",
      "  File \"/opt/homebrew/anaconda3/lib/python3.10/site-packages/IPython/extensions/autoreload.py\", line 261, in check\n",
      "  File \"/opt/homebrew/anaconda3/lib/python3.10/site-packages/IPython/extensions/autoreload.py\", line 459, in superreload\n",
      "  File \"/opt/homebrew/anaconda3/lib/python3.10/importlib/__init__.py\", line 169, in reload\n",
      "    _bootstrap._exec(spec, module)\n",
      "  File \"<frozen importlib._bootstrap>\", line 619, in _exec\n",
      "  File \"<frozen importlib._bootstrap_external>\", line 883, in exec_module\n",
      "  File \"<frozen importlib._bootstrap>\", line 241, in _call_with_frames_removed\n",
      "  File \"/opt/homebrew/anaconda3/lib/python3.10/site-packages/pandas/core/construction.py\", line 54, in <module>\n",
      "    from pandas.core.dtypes.dtypes import NumpyEADtype\n",
      "ImportError: cannot import name 'NumpyEADtype' from 'pandas.core.dtypes.dtypes' (/opt/homebrew/anaconda3/lib/python3.10/site-packages/pandas/core/dtypes/dtypes.py)\n",
      "]\n",
      "[autoreload of pandas.core.algorithms failed: Traceback (most recent call last):\n",
      "  File \"/opt/homebrew/anaconda3/lib/python3.10/site-packages/IPython/extensions/autoreload.py\", line 261, in check\n",
      "  File \"/opt/homebrew/anaconda3/lib/python3.10/site-packages/IPython/extensions/autoreload.py\", line 459, in superreload\n",
      "  File \"/opt/homebrew/anaconda3/lib/python3.10/importlib/__init__.py\", line 169, in reload\n",
      "    _bootstrap._exec(spec, module)\n",
      "  File \"<frozen importlib._bootstrap>\", line 619, in _exec\n",
      "  File \"<frozen importlib._bootstrap_external>\", line 883, in exec_module\n",
      "  File \"<frozen importlib._bootstrap>\", line 241, in _call_with_frames_removed\n",
      "  File \"/opt/homebrew/anaconda3/lib/python3.10/site-packages/pandas/core/algorithms.py\", line 35, in <module>\n",
      "    from pandas.core.dtypes.cast import (\n",
      "ImportError: cannot import name 'np_find_common_type' from 'pandas.core.dtypes.cast' (/opt/homebrew/anaconda3/lib/python3.10/site-packages/pandas/core/dtypes/cast.py)\n",
      "]\n",
      "[autoreload of numexpr.expressions failed: Traceback (most recent call last):\n",
      "  File \"/opt/homebrew/anaconda3/lib/python3.10/site-packages/IPython/extensions/autoreload.py\", line 261, in check\n",
      "  File \"/opt/homebrew/anaconda3/lib/python3.10/site-packages/IPython/extensions/autoreload.py\", line 484, in superreload\n",
      "  File \"/opt/homebrew/anaconda3/lib/python3.10/site-packages/IPython/extensions/autoreload.py\", line 381, in update_generic\n",
      "  File \"/opt/homebrew/anaconda3/lib/python3.10/site-packages/IPython/extensions/autoreload.py\", line 349, in update_class\n",
      "  File \"/opt/homebrew/anaconda3/lib/python3.10/site-packages/IPython/extensions/autoreload.py\", line 307, in update_instances\n",
      "TypeError: can't apply this __setattr__ to Context object\n",
      "]\n",
      "[autoreload of pandas.core.ops.array_ops failed: Traceback (most recent call last):\n",
      "  File \"/opt/homebrew/anaconda3/lib/python3.10/site-packages/IPython/extensions/autoreload.py\", line 261, in check\n",
      "  File \"/opt/homebrew/anaconda3/lib/python3.10/site-packages/IPython/extensions/autoreload.py\", line 459, in superreload\n",
      "  File \"/opt/homebrew/anaconda3/lib/python3.10/importlib/__init__.py\", line 169, in reload\n",
      "    _bootstrap._exec(spec, module)\n",
      "  File \"<frozen importlib._bootstrap>\", line 619, in _exec\n",
      "  File \"<frozen importlib._bootstrap_external>\", line 883, in exec_module\n",
      "  File \"<frozen importlib._bootstrap>\", line 241, in _call_with_frames_removed\n",
      "  File \"/opt/homebrew/anaconda3/lib/python3.10/site-packages/pandas/core/ops/array_ops.py\", line 25, in <module>\n",
      "    from pandas._libs.tslibs import (\n",
      "ImportError: cannot import name 'get_supported_reso' from 'pandas._libs.tslibs' (/opt/homebrew/anaconda3/lib/python3.10/site-packages/pandas/_libs/tslibs/__init__.py)\n",
      "]\n",
      "[autoreload of pandas.core.ops failed: Traceback (most recent call last):\n",
      "  File \"/opt/homebrew/anaconda3/lib/python3.10/site-packages/IPython/extensions/autoreload.py\", line 261, in check\n",
      "  File \"/opt/homebrew/anaconda3/lib/python3.10/site-packages/IPython/extensions/autoreload.py\", line 459, in superreload\n",
      "  File \"/opt/homebrew/anaconda3/lib/python3.10/importlib/__init__.py\", line 169, in reload\n",
      "    _bootstrap._exec(spec, module)\n",
      "  File \"<frozen importlib._bootstrap>\", line 619, in _exec\n",
      "  File \"<frozen importlib._bootstrap_external>\", line 883, in exec_module\n",
      "  File \"<frozen importlib._bootstrap>\", line 241, in _call_with_frames_removed\n",
      "  File \"/opt/homebrew/anaconda3/lib/python3.10/site-packages/pandas/core/ops/__init__.py\", line 8, in <module>\n",
      "    from pandas.core.ops.array_ops import (\n",
      "ImportError: cannot import name 'fill_binop' from 'pandas.core.ops.array_ops' (/opt/homebrew/anaconda3/lib/python3.10/site-packages/pandas/core/ops/array_ops.py)\n",
      "]\n",
      "[autoreload of pandas.core.arrays.base failed: Traceback (most recent call last):\n",
      "  File \"/opt/homebrew/anaconda3/lib/python3.10/site-packages/IPython/extensions/autoreload.py\", line 261, in check\n",
      "  File \"/opt/homebrew/anaconda3/lib/python3.10/site-packages/IPython/extensions/autoreload.py\", line 459, in superreload\n",
      "  File \"/opt/homebrew/anaconda3/lib/python3.10/importlib/__init__.py\", line 169, in reload\n",
      "    _bootstrap._exec(spec, module)\n",
      "  File \"<frozen importlib._bootstrap>\", line 619, in _exec\n",
      "  File \"<frozen importlib._bootstrap_external>\", line 883, in exec_module\n",
      "  File \"<frozen importlib._bootstrap>\", line 241, in _call_with_frames_removed\n",
      "  File \"/opt/homebrew/anaconda3/lib/python3.10/site-packages/pandas/core/arrays/base.py\", line 63, in <module>\n",
      "    from pandas.core.algorithms import (\n",
      "ImportError: cannot import name 'map_array' from 'pandas.core.algorithms' (/opt/homebrew/anaconda3/lib/python3.10/site-packages/pandas/core/algorithms.py)\n",
      "]\n",
      "[autoreload of pandas.core.arrays.arrow.array failed: Traceback (most recent call last):\n",
      "  File \"/opt/homebrew/anaconda3/lib/python3.10/site-packages/IPython/extensions/autoreload.py\", line 261, in check\n",
      "  File \"/opt/homebrew/anaconda3/lib/python3.10/site-packages/IPython/extensions/autoreload.py\", line 459, in superreload\n",
      "  File \"/opt/homebrew/anaconda3/lib/python3.10/importlib/__init__.py\", line 169, in reload\n",
      "    _bootstrap._exec(spec, module)\n",
      "  File \"<frozen importlib._bootstrap>\", line 619, in _exec\n",
      "  File \"<frozen importlib._bootstrap_external>\", line 883, in exec_module\n",
      "  File \"<frozen importlib._bootstrap>\", line 241, in _call_with_frames_removed\n",
      "  File \"/opt/homebrew/anaconda3/lib/python3.10/site-packages/pandas/core/arrays/arrow/array.py\", line 50, in <module>\n",
      "    from pandas.core.arrays.base import (\n",
      "ImportError: cannot import name 'ExtensionArraySupportsAnyAll' from 'pandas.core.arrays.base' (/opt/homebrew/anaconda3/lib/python3.10/site-packages/pandas/core/arrays/base.py)\n",
      "]\n",
      "[autoreload of pandas.core.nanops failed: Traceback (most recent call last):\n",
      "  File \"/opt/homebrew/anaconda3/lib/python3.10/site-packages/IPython/extensions/autoreload.py\", line 261, in check\n",
      "  File \"/opt/homebrew/anaconda3/lib/python3.10/site-packages/IPython/extensions/autoreload.py\", line 484, in superreload\n",
      "  File \"/opt/homebrew/anaconda3/lib/python3.10/site-packages/IPython/extensions/autoreload.py\", line 381, in update_generic\n",
      "  File \"/opt/homebrew/anaconda3/lib/python3.10/site-packages/IPython/extensions/autoreload.py\", line 293, in update_function\n",
      "ValueError: nanmean() requires a code object with 2 free vars, not 4\n",
      "]\n",
      "[autoreload of pandas.core.arrays.boolean failed: Traceback (most recent call last):\n",
      "  File \"/opt/homebrew/anaconda3/lib/python3.10/site-packages/IPython/extensions/autoreload.py\", line 261, in check\n",
      "  File \"/opt/homebrew/anaconda3/lib/python3.10/site-packages/IPython/extensions/autoreload.py\", line 459, in superreload\n",
      "  File \"/opt/homebrew/anaconda3/lib/python3.10/importlib/__init__.py\", line 169, in reload\n",
      "    _bootstrap._exec(spec, module)\n",
      "  File \"<frozen importlib._bootstrap>\", line 619, in _exec\n",
      "  File \"<frozen importlib._bootstrap_external>\", line 883, in exec_module\n",
      "  File \"<frozen importlib._bootstrap>\", line 241, in _call_with_frames_removed\n",
      "  File \"/opt/homebrew/anaconda3/lib/python3.10/site-packages/pandas/core/arrays/boolean.py\", line 40, in <module>\n",
      "    class BooleanDtype(BaseMaskedDtype):\n",
      "  File \"/opt/homebrew/anaconda3/lib/python3.10/site-packages/pandas/core/dtypes/base.py\", line 458, in register_extension_dtype\n",
      "    _registry.register(cls)\n",
      "  File \"/opt/homebrew/anaconda3/lib/python3.10/site-packages/pandas/core/dtypes/base.py\", line 488, in register\n",
      "    raise ValueError(\"can only register pandas extension dtypes\")\n",
      "ValueError: can only register pandas extension dtypes\n",
      "]\n",
      "[autoreload of pandas.core.arrays._mixins failed: Traceback (most recent call last):\n",
      "  File \"/opt/homebrew/anaconda3/lib/python3.10/site-packages/IPython/extensions/autoreload.py\", line 261, in check\n",
      "  File \"/opt/homebrew/anaconda3/lib/python3.10/site-packages/IPython/extensions/autoreload.py\", line 459, in superreload\n",
      "  File \"/opt/homebrew/anaconda3/lib/python3.10/importlib/__init__.py\", line 169, in reload\n",
      "    _bootstrap._exec(spec, module)\n",
      "  File \"<frozen importlib._bootstrap>\", line 619, in _exec\n",
      "  File \"<frozen importlib._bootstrap_external>\", line 883, in exec_module\n",
      "  File \"<frozen importlib._bootstrap>\", line 241, in _call_with_frames_removed\n",
      "  File \"/opt/homebrew/anaconda3/lib/python3.10/site-packages/pandas/core/arrays/_mixins.py\", line 48, in <module>\n",
      "    from pandas.core.algorithms import (\n",
      "ImportError: cannot import name 'value_counts_internal' from 'pandas.core.algorithms' (/opt/homebrew/anaconda3/lib/python3.10/site-packages/pandas/core/algorithms.py)\n",
      "]\n",
      "[autoreload of pandas.core.strings.accessor failed: Traceback (most recent call last):\n",
      "  File \"/opt/homebrew/anaconda3/lib/python3.10/site-packages/IPython/extensions/autoreload.py\", line 261, in check\n",
      "  File \"/opt/homebrew/anaconda3/lib/python3.10/site-packages/IPython/extensions/autoreload.py\", line 459, in superreload\n",
      "  File \"/opt/homebrew/anaconda3/lib/python3.10/importlib/__init__.py\", line 169, in reload\n",
      "    _bootstrap._exec(spec, module)\n",
      "  File \"<frozen importlib._bootstrap>\", line 619, in _exec\n",
      "  File \"<frozen importlib._bootstrap_external>\", line 883, in exec_module\n",
      "  File \"<frozen importlib._bootstrap>\", line 241, in _call_with_frames_removed\n",
      "  File \"/opt/homebrew/anaconda3/lib/python3.10/site-packages/pandas/core/strings/accessor.py\", line 35, in <module>\n",
      "    from pandas.core.dtypes.dtypes import (\n",
      "ImportError: cannot import name 'ArrowDtype' from 'pandas.core.dtypes.dtypes' (/opt/homebrew/anaconda3/lib/python3.10/site-packages/pandas/core/dtypes/dtypes.py)\n",
      "]\n",
      "[autoreload of pandas.core.arrays.categorical failed: Traceback (most recent call last):\n",
      "  File \"/opt/homebrew/anaconda3/lib/python3.10/site-packages/IPython/extensions/autoreload.py\", line 261, in check\n",
      "  File \"/opt/homebrew/anaconda3/lib/python3.10/site-packages/IPython/extensions/autoreload.py\", line 459, in superreload\n",
      "  File \"/opt/homebrew/anaconda3/lib/python3.10/importlib/__init__.py\", line 169, in reload\n",
      "    _bootstrap._exec(spec, module)\n",
      "  File \"<frozen importlib._bootstrap>\", line 619, in _exec\n",
      "  File \"<frozen importlib._bootstrap_external>\", line 883, in exec_module\n",
      "  File \"<frozen importlib._bootstrap>\", line 241, in _call_with_frames_removed\n",
      "  File \"/opt/homebrew/anaconda3/lib/python3.10/site-packages/pandas/core/arrays/categorical.py\", line 33, in <module>\n",
      "    from pandas.core.dtypes.common import (\n",
      "ImportError: cannot import name 'is_any_real_numeric_dtype' from 'pandas.core.dtypes.common' (/opt/homebrew/anaconda3/lib/python3.10/site-packages/pandas/core/dtypes/common.py)\n",
      "]\n",
      "[autoreload of pandas.core.arrays.integer failed: Traceback (most recent call last):\n",
      "  File \"/opt/homebrew/anaconda3/lib/python3.10/site-packages/IPython/extensions/autoreload.py\", line 261, in check\n",
      "  File \"/opt/homebrew/anaconda3/lib/python3.10/site-packages/IPython/extensions/autoreload.py\", line 459, in superreload\n",
      "  File \"/opt/homebrew/anaconda3/lib/python3.10/importlib/__init__.py\", line 169, in reload\n",
      "    _bootstrap._exec(spec, module)\n",
      "  File \"<frozen importlib._bootstrap>\", line 619, in _exec\n",
      "  File \"<frozen importlib._bootstrap_external>\", line 883, in exec_module\n",
      "  File \"<frozen importlib._bootstrap>\", line 241, in _call_with_frames_removed\n",
      "  File \"/opt/homebrew/anaconda3/lib/python3.10/site-packages/pandas/core/arrays/integer.py\", line 206, in <module>\n",
      "    class Int8Dtype(IntegerDtype):\n",
      "  File \"/opt/homebrew/anaconda3/lib/python3.10/site-packages/pandas/core/dtypes/base.py\", line 458, in register_extension_dtype\n",
      "    _registry.register(cls)\n",
      "  File \"/opt/homebrew/anaconda3/lib/python3.10/site-packages/pandas/core/dtypes/base.py\", line 488, in register\n",
      "    raise ValueError(\"can only register pandas extension dtypes\")\n",
      "ValueError: can only register pandas extension dtypes\n",
      "]\n",
      "[autoreload of pandas.core.arrays.datetimelike failed: Traceback (most recent call last):\n",
      "  File \"/opt/homebrew/anaconda3/lib/python3.10/site-packages/IPython/extensions/autoreload.py\", line 261, in check\n",
      "  File \"/opt/homebrew/anaconda3/lib/python3.10/site-packages/IPython/extensions/autoreload.py\", line 459, in superreload\n",
      "  File \"/opt/homebrew/anaconda3/lib/python3.10/importlib/__init__.py\", line 169, in reload\n",
      "    _bootstrap._exec(spec, module)\n",
      "  File \"<frozen importlib._bootstrap>\", line 619, in _exec\n",
      "  File \"<frozen importlib._bootstrap_external>\", line 883, in exec_module\n",
      "  File \"<frozen importlib._bootstrap>\", line 241, in _call_with_frames_removed\n",
      "  File \"/opt/homebrew/anaconda3/lib/python3.10/site-packages/pandas/core/arrays/datetimelike.py\", line 112, in <module>\n",
      "    from pandas.core.algorithms import (\n",
      "ImportError: cannot import name 'map_array' from 'pandas.core.algorithms' (/opt/homebrew/anaconda3/lib/python3.10/site-packages/pandas/core/algorithms.py)\n",
      "]\n",
      "[autoreload of pandas.core.arrays.datetimes failed: Traceback (most recent call last):\n",
      "  File \"/opt/homebrew/anaconda3/lib/python3.10/site-packages/IPython/extensions/autoreload.py\", line 261, in check\n",
      "  File \"/opt/homebrew/anaconda3/lib/python3.10/site-packages/IPython/extensions/autoreload.py\", line 459, in superreload\n",
      "  File \"/opt/homebrew/anaconda3/lib/python3.10/importlib/__init__.py\", line 169, in reload\n",
      "    _bootstrap._exec(spec, module)\n",
      "  File \"<frozen importlib._bootstrap>\", line 619, in _exec\n",
      "  File \"<frozen importlib._bootstrap_external>\", line 883, in exec_module\n",
      "  File \"<frozen importlib._bootstrap>\", line 241, in _call_with_frames_removed\n",
      "  File \"/opt/homebrew/anaconda3/lib/python3.10/site-packages/pandas/core/arrays/datetimes.py\", line 20, in <module>\n",
      "    from pandas._libs.tslibs import (\n",
      "ImportError: cannot import name 'get_supported_reso' from 'pandas._libs.tslibs' (/opt/homebrew/anaconda3/lib/python3.10/site-packages/pandas/_libs/tslibs/__init__.py)\n",
      "]\n",
      "[autoreload of pandas.core.arrays.floating failed: Traceback (most recent call last):\n",
      "  File \"/opt/homebrew/anaconda3/lib/python3.10/site-packages/IPython/extensions/autoreload.py\", line 261, in check\n",
      "  File \"/opt/homebrew/anaconda3/lib/python3.10/site-packages/IPython/extensions/autoreload.py\", line 459, in superreload\n",
      "  File \"/opt/homebrew/anaconda3/lib/python3.10/importlib/__init__.py\", line 169, in reload\n",
      "    _bootstrap._exec(spec, module)\n",
      "  File \"<frozen importlib._bootstrap>\", line 619, in _exec\n",
      "  File \"<frozen importlib._bootstrap_external>\", line 883, in exec_module\n",
      "  File \"<frozen importlib._bootstrap>\", line 241, in _call_with_frames_removed\n",
      "  File \"/opt/homebrew/anaconda3/lib/python3.10/site-packages/pandas/core/arrays/floating.py\", line 157, in <module>\n",
      "    class Float32Dtype(FloatingDtype):\n",
      "  File \"/opt/homebrew/anaconda3/lib/python3.10/site-packages/pandas/core/dtypes/base.py\", line 458, in register_extension_dtype\n",
      "    _registry.register(cls)\n",
      "  File \"/opt/homebrew/anaconda3/lib/python3.10/site-packages/pandas/core/dtypes/base.py\", line 488, in register\n",
      "    raise ValueError(\"can only register pandas extension dtypes\")\n",
      "ValueError: can only register pandas extension dtypes\n",
      "]\n",
      "[autoreload of pandas.core.arrays.sparse.array failed: Traceback (most recent call last):\n",
      "  File \"/opt/homebrew/anaconda3/lib/python3.10/site-packages/IPython/extensions/autoreload.py\", line 261, in check\n",
      "  File \"/opt/homebrew/anaconda3/lib/python3.10/site-packages/IPython/extensions/autoreload.py\", line 459, in superreload\n",
      "  File \"/opt/homebrew/anaconda3/lib/python3.10/importlib/__init__.py\", line 169, in reload\n",
      "    _bootstrap._exec(spec, module)\n",
      "  File \"<frozen importlib._bootstrap>\", line 619, in _exec\n",
      "  File \"<frozen importlib._bootstrap_external>\", line 883, in exec_module\n",
      "  File \"<frozen importlib._bootstrap>\", line 241, in _call_with_frames_removed\n",
      "  File \"/opt/homebrew/anaconda3/lib/python3.10/site-packages/pandas/core/arrays/sparse/array.py\", line 52, in <module>\n",
      "    from pandas.core.dtypes.dtypes import (\n",
      "ImportError: cannot import name 'SparseDtype' from 'pandas.core.dtypes.dtypes' (/opt/homebrew/anaconda3/lib/python3.10/site-packages/pandas/core/dtypes/dtypes.py)\n",
      "]\n",
      "[autoreload of pandas.core.arrays.sparse.accessor failed: Traceback (most recent call last):\n",
      "  File \"/opt/homebrew/anaconda3/lib/python3.10/site-packages/IPython/extensions/autoreload.py\", line 261, in check\n",
      "  File \"/opt/homebrew/anaconda3/lib/python3.10/site-packages/IPython/extensions/autoreload.py\", line 459, in superreload\n",
      "  File \"/opt/homebrew/anaconda3/lib/python3.10/importlib/__init__.py\", line 169, in reload\n",
      "    _bootstrap._exec(spec, module)\n",
      "  File \"<frozen importlib._bootstrap>\", line 619, in _exec\n",
      "  File \"<frozen importlib._bootstrap_external>\", line 883, in exec_module\n",
      "  File \"<frozen importlib._bootstrap>\", line 241, in _call_with_frames_removed\n",
      "  File \"/opt/homebrew/anaconda3/lib/python3.10/site-packages/pandas/core/arrays/sparse/accessor.py\", line 11, in <module>\n",
      "    from pandas.core.dtypes.dtypes import SparseDtype\n",
      "ImportError: cannot import name 'SparseDtype' from 'pandas.core.dtypes.dtypes' (/opt/homebrew/anaconda3/lib/python3.10/site-packages/pandas/core/dtypes/dtypes.py)\n",
      "]\n",
      "[autoreload of pandas.core.arrays.numpy_ failed: Traceback (most recent call last):\n",
      "  File \"/opt/homebrew/anaconda3/lib/python3.10/site-packages/IPython/extensions/autoreload.py\", line 261, in check\n",
      "  File \"/opt/homebrew/anaconda3/lib/python3.10/site-packages/IPython/extensions/autoreload.py\", line 459, in superreload\n",
      "  File \"/opt/homebrew/anaconda3/lib/python3.10/importlib/__init__.py\", line 169, in reload\n",
      "    _bootstrap._exec(spec, module)\n",
      "  File \"<frozen importlib._bootstrap>\", line 619, in _exec\n",
      "  File \"<frozen importlib._bootstrap_external>\", line 883, in exec_module\n",
      "  File \"<frozen importlib._bootstrap>\", line 241, in _call_with_frames_removed\n",
      "  File \"/opt/homebrew/anaconda3/lib/python3.10/site-packages/pandas/core/arrays/numpy_.py\", line 20, in <module>\n",
      "    from pandas.core.dtypes.dtypes import NumpyEADtype\n",
      "ImportError: cannot import name 'NumpyEADtype' from 'pandas.core.dtypes.dtypes' (/opt/homebrew/anaconda3/lib/python3.10/site-packages/pandas/core/dtypes/dtypes.py)\n",
      "]\n",
      "[autoreload of pandas.core.arrays.string_ failed: Traceback (most recent call last):\n",
      "  File \"/opt/homebrew/anaconda3/lib/python3.10/site-packages/IPython/extensions/autoreload.py\", line 261, in check\n",
      "  File \"/opt/homebrew/anaconda3/lib/python3.10/site-packages/IPython/extensions/autoreload.py\", line 459, in superreload\n",
      "  File \"/opt/homebrew/anaconda3/lib/python3.10/importlib/__init__.py\", line 169, in reload\n",
      "    _bootstrap._exec(spec, module)\n",
      "  File \"<frozen importlib._bootstrap>\", line 619, in _exec\n",
      "  File \"<frozen importlib._bootstrap_external>\", line 883, in exec_module\n",
      "  File \"<frozen importlib._bootstrap>\", line 241, in _call_with_frames_removed\n",
      "  File \"/opt/homebrew/anaconda3/lib/python3.10/site-packages/pandas/core/arrays/string_.py\", line 47, in <module>\n",
      "    from pandas.core.arrays.numpy_ import NumpyExtensionArray\n",
      "ImportError: cannot import name 'NumpyExtensionArray' from 'pandas.core.arrays.numpy_' (/opt/homebrew/anaconda3/lib/python3.10/site-packages/pandas/core/arrays/numpy_.py)\n",
      "]\n",
      "[autoreload of pandas.core.indexes.base failed: Traceback (most recent call last):\n",
      "  File \"/opt/homebrew/anaconda3/lib/python3.10/site-packages/IPython/extensions/autoreload.py\", line 261, in check\n",
      "  File \"/opt/homebrew/anaconda3/lib/python3.10/site-packages/IPython/extensions/autoreload.py\", line 459, in superreload\n",
      "  File \"/opt/homebrew/anaconda3/lib/python3.10/importlib/__init__.py\", line 169, in reload\n",
      "    _bootstrap._exec(spec, module)\n",
      "  File \"<frozen importlib._bootstrap>\", line 619, in _exec\n",
      "  File \"<frozen importlib._bootstrap_external>\", line 883, in exec_module\n",
      "  File \"<frozen importlib._bootstrap>\", line 241, in _call_with_frames_removed\n",
      "  File \"/opt/homebrew/anaconda3/lib/python3.10/site-packages/pandas/core/indexes/base.py\", line 34, in <module>\n",
      "    from pandas._libs.internals import BlockValuesRefs\n",
      "ImportError: cannot import name 'BlockValuesRefs' from 'pandas._libs.internals' (/opt/homebrew/anaconda3/lib/python3.10/site-packages/pandas/_libs/internals.cpython-310-darwin.so)\n",
      "]\n",
      "[autoreload of pandas.core.arrays.interval failed: Traceback (most recent call last):\n",
      "  File \"/opt/homebrew/anaconda3/lib/python3.10/site-packages/IPython/extensions/autoreload.py\", line 261, in check\n",
      "  File \"/opt/homebrew/anaconda3/lib/python3.10/site-packages/IPython/extensions/autoreload.py\", line 459, in superreload\n",
      "  File \"/opt/homebrew/anaconda3/lib/python3.10/importlib/__init__.py\", line 169, in reload\n",
      "    _bootstrap._exec(spec, module)\n",
      "  File \"<frozen importlib._bootstrap>\", line 619, in _exec\n",
      "  File \"<frozen importlib._bootstrap_external>\", line 883, in exec_module\n",
      "  File \"<frozen importlib._bootstrap>\", line 241, in _call_with_frames_removed\n",
      "  File \"/opt/homebrew/anaconda3/lib/python3.10/site-packages/pandas/core/arrays/interval.py\", line 47, in <module>\n",
      "    from pandas.core.dtypes.cast import (\n",
      "ImportError: cannot import name 'maybe_upcast_numeric_to_64bit' from 'pandas.core.dtypes.cast' (/opt/homebrew/anaconda3/lib/python3.10/site-packages/pandas/core/dtypes/cast.py)\n",
      "]\n",
      "[autoreload of pandas.core.arrays.period failed: Traceback (most recent call last):\n",
      "  File \"/opt/homebrew/anaconda3/lib/python3.10/site-packages/IPython/extensions/autoreload.py\", line 261, in check\n",
      "  File \"/opt/homebrew/anaconda3/lib/python3.10/site-packages/IPython/extensions/autoreload.py\", line 484, in superreload\n",
      "  File \"/opt/homebrew/anaconda3/lib/python3.10/site-packages/IPython/extensions/autoreload.py\", line 381, in update_generic\n",
      "  File \"/opt/homebrew/anaconda3/lib/python3.10/site-packages/IPython/extensions/autoreload.py\", line 333, in update_class\n",
      "  File \"/opt/homebrew/anaconda3/lib/python3.10/site-packages/IPython/extensions/autoreload.py\", line 381, in update_generic\n",
      "  File \"/opt/homebrew/anaconda3/lib/python3.10/site-packages/IPython/extensions/autoreload.py\", line 293, in update_function\n",
      "ValueError: _format_native_types() requires a code object with 1 free vars, not 0\n",
      "]\n",
      "[autoreload of pandas.core.arrays.string_arrow failed: Traceback (most recent call last):\n",
      "  File \"/opt/homebrew/anaconda3/lib/python3.10/site-packages/IPython/extensions/autoreload.py\", line 261, in check\n",
      "  File \"/opt/homebrew/anaconda3/lib/python3.10/site-packages/IPython/extensions/autoreload.py\", line 484, in superreload\n",
      "  File \"/opt/homebrew/anaconda3/lib/python3.10/site-packages/IPython/extensions/autoreload.py\", line 381, in update_generic\n",
      "  File \"/opt/homebrew/anaconda3/lib/python3.10/site-packages/IPython/extensions/autoreload.py\", line 333, in update_class\n",
      "  File \"/opt/homebrew/anaconda3/lib/python3.10/site-packages/IPython/extensions/autoreload.py\", line 381, in update_generic\n",
      "  File \"/opt/homebrew/anaconda3/lib/python3.10/site-packages/IPython/extensions/autoreload.py\", line 293, in update_function\n",
      "ValueError: _maybe_convert_setitem_value() requires a code object with 0 free vars, not 1\n",
      "]\n",
      "[autoreload of pandas.core.arrays.timedeltas failed: Traceback (most recent call last):\n",
      "  File \"/opt/homebrew/anaconda3/lib/python3.10/site-packages/IPython/extensions/autoreload.py\", line 261, in check\n",
      "  File \"/opt/homebrew/anaconda3/lib/python3.10/site-packages/IPython/extensions/autoreload.py\", line 459, in superreload\n",
      "  File \"/opt/homebrew/anaconda3/lib/python3.10/importlib/__init__.py\", line 169, in reload\n",
      "    _bootstrap._exec(spec, module)\n",
      "  File \"<frozen importlib._bootstrap>\", line 619, in _exec\n",
      "  File \"<frozen importlib._bootstrap_external>\", line 883, in exec_module\n",
      "  File \"<frozen importlib._bootstrap>\", line 241, in _call_with_frames_removed\n",
      "  File \"/opt/homebrew/anaconda3/lib/python3.10/site-packages/pandas/core/arrays/timedeltas.py\", line 17, in <module>\n",
      "    from pandas._libs.tslibs import (\n",
      "ImportError: cannot import name 'get_supported_reso' from 'pandas._libs.tslibs' (/opt/homebrew/anaconda3/lib/python3.10/site-packages/pandas/_libs/tslibs/__init__.py)\n",
      "]\n",
      "[autoreload of pandas.core.arrays failed: Traceback (most recent call last):\n",
      "  File \"/opt/homebrew/anaconda3/lib/python3.10/site-packages/IPython/extensions/autoreload.py\", line 261, in check\n",
      "  File \"/opt/homebrew/anaconda3/lib/python3.10/site-packages/IPython/extensions/autoreload.py\", line 459, in superreload\n",
      "  File \"/opt/homebrew/anaconda3/lib/python3.10/importlib/__init__.py\", line 169, in reload\n",
      "    _bootstrap._exec(spec, module)\n",
      "  File \"<frozen importlib._bootstrap>\", line 619, in _exec\n",
      "  File \"<frozen importlib._bootstrap_external>\", line 883, in exec_module\n",
      "  File \"<frozen importlib._bootstrap>\", line 241, in _call_with_frames_removed\n",
      "  File \"/opt/homebrew/anaconda3/lib/python3.10/site-packages/pandas/core/arrays/__init__.py\", line 14, in <module>\n",
      "    from pandas.core.arrays.numpy_ import NumpyExtensionArray\n",
      "ImportError: cannot import name 'NumpyExtensionArray' from 'pandas.core.arrays.numpy_' (/opt/homebrew/anaconda3/lib/python3.10/site-packages/pandas/core/arrays/numpy_.py)\n",
      "]\n",
      "[autoreload of pandas.core.apply failed: Traceback (most recent call last):\n",
      "  File \"/opt/homebrew/anaconda3/lib/python3.10/site-packages/IPython/extensions/autoreload.py\", line 261, in check\n",
      "  File \"/opt/homebrew/anaconda3/lib/python3.10/site-packages/IPython/extensions/autoreload.py\", line 484, in superreload\n",
      "  File \"/opt/homebrew/anaconda3/lib/python3.10/site-packages/IPython/extensions/autoreload.py\", line 381, in update_generic\n",
      "  File \"/opt/homebrew/anaconda3/lib/python3.10/site-packages/IPython/extensions/autoreload.py\", line 333, in update_class\n",
      "  File \"/opt/homebrew/anaconda3/lib/python3.10/site-packages/IPython/extensions/autoreload.py\", line 381, in update_generic\n",
      "  File \"/opt/homebrew/anaconda3/lib/python3.10/site-packages/IPython/extensions/autoreload.py\", line 293, in update_function\n",
      "ValueError: apply_broadcast() requires a code object with 1 free vars, not 0\n",
      "]\n",
      "[autoreload of pandas.core.indexes.category failed: Traceback (most recent call last):\n",
      "  File \"/opt/homebrew/anaconda3/lib/python3.10/site-packages/IPython/extensions/autoreload.py\", line 261, in check\n",
      "  File \"/opt/homebrew/anaconda3/lib/python3.10/site-packages/IPython/extensions/autoreload.py\", line 484, in superreload\n",
      "  File \"/opt/homebrew/anaconda3/lib/python3.10/site-packages/IPython/extensions/autoreload.py\", line 381, in update_generic\n",
      "  File \"/opt/homebrew/anaconda3/lib/python3.10/site-packages/IPython/extensions/autoreload.py\", line 333, in update_class\n",
      "  File \"/opt/homebrew/anaconda3/lib/python3.10/site-packages/IPython/extensions/autoreload.py\", line 381, in update_generic\n",
      "  File \"/opt/homebrew/anaconda3/lib/python3.10/site-packages/IPython/extensions/autoreload.py\", line 293, in update_function\n",
      "ValueError: astype() requires a code object with 1 free vars, not 0\n",
      "]\n",
      "[autoreload of pandas.core.indexes.range failed: Traceback (most recent call last):\n",
      "  File \"/opt/homebrew/anaconda3/lib/python3.10/site-packages/IPython/extensions/autoreload.py\", line 261, in check\n",
      "  File \"/opt/homebrew/anaconda3/lib/python3.10/site-packages/IPython/extensions/autoreload.py\", line 484, in superreload\n",
      "  File \"/opt/homebrew/anaconda3/lib/python3.10/site-packages/IPython/extensions/autoreload.py\", line 381, in update_generic\n",
      "  File \"/opt/homebrew/anaconda3/lib/python3.10/site-packages/IPython/extensions/autoreload.py\", line 333, in update_class\n",
      "  File \"/opt/homebrew/anaconda3/lib/python3.10/site-packages/IPython/extensions/autoreload.py\", line 381, in update_generic\n",
      "  File \"/opt/homebrew/anaconda3/lib/python3.10/site-packages/IPython/extensions/autoreload.py\", line 293, in update_function\n",
      "ValueError: get_loc() requires a code object with 1 free vars, not 0\n",
      "]\n",
      "[autoreload of pandas.core.tools.timedeltas failed: Traceback (most recent call last):\n",
      "  File \"/opt/homebrew/anaconda3/lib/python3.10/site-packages/IPython/extensions/autoreload.py\", line 261, in check\n",
      "  File \"/opt/homebrew/anaconda3/lib/python3.10/site-packages/IPython/extensions/autoreload.py\", line 459, in superreload\n",
      "  File \"/opt/homebrew/anaconda3/lib/python3.10/importlib/__init__.py\", line 169, in reload\n",
      "    _bootstrap._exec(spec, module)\n",
      "  File \"<frozen importlib._bootstrap>\", line 619, in _exec\n",
      "  File \"<frozen importlib._bootstrap_external>\", line 883, in exec_module\n",
      "  File \"<frozen importlib._bootstrap>\", line 241, in _call_with_frames_removed\n",
      "  File \"/opt/homebrew/anaconda3/lib/python3.10/site-packages/pandas/core/tools/timedeltas.py\", line 26, in <module>\n",
      "    from pandas.core.dtypes.dtypes import ArrowDtype\n",
      "ImportError: cannot import name 'ArrowDtype' from 'pandas.core.dtypes.dtypes' (/opt/homebrew/anaconda3/lib/python3.10/site-packages/pandas/core/dtypes/dtypes.py)\n",
      "]\n",
      "[autoreload of pandas.core.indexes.datetimelike failed: Traceback (most recent call last):\n",
      "  File \"/opt/homebrew/anaconda3/lib/python3.10/site-packages/IPython/extensions/autoreload.py\", line 261, in check\n",
      "  File \"/opt/homebrew/anaconda3/lib/python3.10/site-packages/IPython/extensions/autoreload.py\", line 484, in superreload\n",
      "  File \"/opt/homebrew/anaconda3/lib/python3.10/site-packages/IPython/extensions/autoreload.py\", line 381, in update_generic\n",
      "  File \"/opt/homebrew/anaconda3/lib/python3.10/site-packages/IPython/extensions/autoreload.py\", line 333, in update_class\n",
      "  File \"/opt/homebrew/anaconda3/lib/python3.10/site-packages/IPython/extensions/autoreload.py\", line 381, in update_generic\n",
      "  File \"/opt/homebrew/anaconda3/lib/python3.10/site-packages/IPython/extensions/autoreload.py\", line 293, in update_function\n",
      "ValueError: mean() requires a code object with 2 free vars, not 0\n",
      "]\n",
      "[autoreload of pandas.core.indexes.multi failed: Traceback (most recent call last):\n",
      "  File \"/opt/homebrew/anaconda3/lib/python3.10/site-packages/IPython/extensions/autoreload.py\", line 261, in check\n",
      "  File \"/opt/homebrew/anaconda3/lib/python3.10/site-packages/IPython/extensions/autoreload.py\", line 484, in superreload\n",
      "  File \"/opt/homebrew/anaconda3/lib/python3.10/site-packages/IPython/extensions/autoreload.py\", line 381, in update_generic\n",
      "  File \"/opt/homebrew/anaconda3/lib/python3.10/site-packages/IPython/extensions/autoreload.py\", line 333, in update_class\n",
      "  File \"/opt/homebrew/anaconda3/lib/python3.10/site-packages/IPython/extensions/autoreload.py\", line 381, in update_generic\n",
      "  File \"/opt/homebrew/anaconda3/lib/python3.10/site-packages/IPython/extensions/autoreload.py\", line 293, in update_function\n",
      "ValueError: set_levels() requires a code object with 4 free vars, not 0\n",
      "]\n",
      "[autoreload of pandas.core.indexes.interval failed: Traceback (most recent call last):\n",
      "  File \"/opt/homebrew/anaconda3/lib/python3.10/site-packages/IPython/extensions/autoreload.py\", line 261, in check\n",
      "  File \"/opt/homebrew/anaconda3/lib/python3.10/site-packages/IPython/extensions/autoreload.py\", line 459, in superreload\n",
      "  File \"/opt/homebrew/anaconda3/lib/python3.10/importlib/__init__.py\", line 169, in reload\n",
      "    _bootstrap._exec(spec, module)\n",
      "  File \"<frozen importlib._bootstrap>\", line 619, in _exec\n",
      "  File \"<frozen importlib._bootstrap_external>\", line 883, in exec_module\n",
      "  File \"<frozen importlib._bootstrap>\", line 241, in _call_with_frames_removed\n",
      "  File \"/opt/homebrew/anaconda3/lib/python3.10/site-packages/pandas/core/indexes/interval.py\", line 36, in <module>\n",
      "    from pandas.core.dtypes.cast import (\n",
      "ImportError: cannot import name 'maybe_upcast_numeric_to_64bit' from 'pandas.core.dtypes.cast' (/opt/homebrew/anaconda3/lib/python3.10/site-packages/pandas/core/dtypes/cast.py)\n",
      "]\n",
      "[autoreload of pandas.core.indexes.period failed: Traceback (most recent call last):\n",
      "  File \"/opt/homebrew/anaconda3/lib/python3.10/site-packages/IPython/extensions/autoreload.py\", line 261, in check\n",
      "  File \"/opt/homebrew/anaconda3/lib/python3.10/site-packages/IPython/extensions/autoreload.py\", line 484, in superreload\n",
      "  File \"/opt/homebrew/anaconda3/lib/python3.10/site-packages/IPython/extensions/autoreload.py\", line 381, in update_generic\n",
      "  File \"/opt/homebrew/anaconda3/lib/python3.10/site-packages/IPython/extensions/autoreload.py\", line 333, in update_class\n",
      "  File \"/opt/homebrew/anaconda3/lib/python3.10/site-packages/IPython/extensions/autoreload.py\", line 381, in update_generic\n",
      "  File \"/opt/homebrew/anaconda3/lib/python3.10/site-packages/IPython/extensions/autoreload.py\", line 333, in update_class\n",
      "  File \"/opt/homebrew/anaconda3/lib/python3.10/site-packages/IPython/extensions/autoreload.py\", line 381, in update_generic\n",
      "  File \"/opt/homebrew/anaconda3/lib/python3.10/site-packages/IPython/extensions/autoreload.py\", line 293, in update_function\n",
      "ValueError: _format_native_types() requires a code object with 1 free vars, not 0\n",
      "]\n",
      "[autoreload of pandas.core.internals.blocks failed: Traceback (most recent call last):\n",
      "  File \"/opt/homebrew/anaconda3/lib/python3.10/site-packages/IPython/extensions/autoreload.py\", line 261, in check\n",
      "  File \"/opt/homebrew/anaconda3/lib/python3.10/site-packages/IPython/extensions/autoreload.py\", line 459, in superreload\n",
      "  File \"/opt/homebrew/anaconda3/lib/python3.10/importlib/__init__.py\", line 169, in reload\n",
      "    _bootstrap._exec(spec, module)\n",
      "  File \"<frozen importlib._bootstrap>\", line 619, in _exec\n",
      "  File \"<frozen importlib._bootstrap_external>\", line 883, in exec_module\n",
      "  File \"<frozen importlib._bootstrap>\", line 241, in _call_with_frames_removed\n",
      "  File \"/opt/homebrew/anaconda3/lib/python3.10/site-packages/pandas/core/internals/blocks.py\", line 26, in <module>\n",
      "    from pandas._libs.internals import (\n",
      "ImportError: cannot import name 'BlockValuesRefs' from 'pandas._libs.internals' (/opt/homebrew/anaconda3/lib/python3.10/site-packages/pandas/_libs/internals.cpython-310-darwin.so)\n",
      "]\n",
      "[autoreload of pandas.core.internals.base failed: Traceback (most recent call last):\n",
      "  File \"/opt/homebrew/anaconda3/lib/python3.10/site-packages/IPython/extensions/autoreload.py\", line 261, in check\n",
      "  File \"/opt/homebrew/anaconda3/lib/python3.10/site-packages/IPython/extensions/autoreload.py\", line 459, in superreload\n",
      "  File \"/opt/homebrew/anaconda3/lib/python3.10/importlib/__init__.py\", line 169, in reload\n",
      "    _bootstrap._exec(spec, module)\n",
      "  File \"<frozen importlib._bootstrap>\", line 619, in _exec\n",
      "  File \"<frozen importlib._bootstrap_external>\", line 883, in exec_module\n",
      "  File \"<frozen importlib._bootstrap>\", line 241, in _call_with_frames_removed\n",
      "  File \"/opt/homebrew/anaconda3/lib/python3.10/site-packages/pandas/core/internals/base.py\", line 30, in <module>\n",
      "    from pandas.core.dtypes.dtypes import (\n",
      "ImportError: cannot import name 'SparseDtype' from 'pandas.core.dtypes.dtypes' (/opt/homebrew/anaconda3/lib/python3.10/site-packages/pandas/core/dtypes/dtypes.py)\n",
      "]\n",
      "[autoreload of pandas.core.internals.array_manager failed: Traceback (most recent call last):\n",
      "  File \"/opt/homebrew/anaconda3/lib/python3.10/site-packages/IPython/extensions/autoreload.py\", line 261, in check\n",
      "  File \"/opt/homebrew/anaconda3/lib/python3.10/site-packages/IPython/extensions/autoreload.py\", line 459, in superreload\n",
      "  File \"/opt/homebrew/anaconda3/lib/python3.10/importlib/__init__.py\", line 169, in reload\n",
      "    _bootstrap._exec(spec, module)\n",
      "  File \"<frozen importlib._bootstrap>\", line 619, in _exec\n",
      "  File \"<frozen importlib._bootstrap_external>\", line 883, in exec_module\n",
      "  File \"<frozen importlib._bootstrap>\", line 241, in _call_with_frames_removed\n",
      "  File \"/opt/homebrew/anaconda3/lib/python3.10/site-packages/pandas/core/internals/array_manager.py\", line 24, in <module>\n",
      "    from pandas.core.dtypes.cast import (\n",
      "ImportError: cannot import name 'np_find_common_type' from 'pandas.core.dtypes.cast' (/opt/homebrew/anaconda3/lib/python3.10/site-packages/pandas/core/dtypes/cast.py)\n",
      "]\n",
      "[autoreload of pandas.core.internals.managers failed: Traceback (most recent call last):\n",
      "  File \"/opt/homebrew/anaconda3/lib/python3.10/site-packages/IPython/extensions/autoreload.py\", line 261, in check\n",
      "  File \"/opt/homebrew/anaconda3/lib/python3.10/site-packages/IPython/extensions/autoreload.py\", line 459, in superreload\n",
      "  File \"/opt/homebrew/anaconda3/lib/python3.10/importlib/__init__.py\", line 169, in reload\n",
      "    _bootstrap._exec(spec, module)\n",
      "  File \"<frozen importlib._bootstrap>\", line 619, in _exec\n",
      "  File \"<frozen importlib._bootstrap_external>\", line 883, in exec_module\n",
      "  File \"<frozen importlib._bootstrap>\", line 241, in _call_with_frames_removed\n",
      "  File \"/opt/homebrew/anaconda3/lib/python3.10/site-packages/pandas/core/internals/managers.py\", line 25, in <module>\n",
      "    from pandas._libs.internals import (\n",
      "ImportError: cannot import name 'BlockValuesRefs' from 'pandas._libs.internals' (/opt/homebrew/anaconda3/lib/python3.10/site-packages/pandas/_libs/internals.cpython-310-darwin.so)\n",
      "]\n",
      "[autoreload of pandas.core.internals.concat failed: Traceback (most recent call last):\n",
      "  File \"/opt/homebrew/anaconda3/lib/python3.10/site-packages/IPython/extensions/autoreload.py\", line 261, in check\n",
      "  File \"/opt/homebrew/anaconda3/lib/python3.10/site-packages/IPython/extensions/autoreload.py\", line 459, in superreload\n",
      "  File \"/opt/homebrew/anaconda3/lib/python3.10/importlib/__init__.py\", line 169, in reload\n",
      "    _bootstrap._exec(spec, module)\n",
      "  File \"<frozen importlib._bootstrap>\", line 619, in _exec\n",
      "  File \"<frozen importlib._bootstrap_external>\", line 883, in exec_module\n",
      "  File \"<frozen importlib._bootstrap>\", line 241, in _call_with_frames_removed\n",
      "  File \"/opt/homebrew/anaconda3/lib/python3.10/site-packages/pandas/core/internals/concat.py\", line 31, in <module>\n",
      "    from pandas.core.dtypes.dtypes import (\n",
      "ImportError: cannot import name 'SparseDtype' from 'pandas.core.dtypes.dtypes' (/opt/homebrew/anaconda3/lib/python3.10/site-packages/pandas/core/dtypes/dtypes.py)\n",
      "]\n",
      "[autoreload of pandas.core.reshape.concat failed: Traceback (most recent call last):\n",
      "  File \"/opt/homebrew/anaconda3/lib/python3.10/site-packages/IPython/extensions/autoreload.py\", line 261, in check\n",
      "  File \"/opt/homebrew/anaconda3/lib/python3.10/site-packages/IPython/extensions/autoreload.py\", line 484, in superreload\n",
      "  File \"/opt/homebrew/anaconda3/lib/python3.10/site-packages/IPython/extensions/autoreload.py\", line 381, in update_generic\n",
      "  File \"/opt/homebrew/anaconda3/lib/python3.10/site-packages/IPython/extensions/autoreload.py\", line 293, in update_function\n",
      "ValueError: concat() requires a code object with 4 free vars, not 0\n",
      "]\n",
      "[autoreload of pandas.io.formats.format failed: Traceback (most recent call last):\n",
      "  File \"/opt/homebrew/anaconda3/lib/python3.10/site-packages/IPython/extensions/autoreload.py\", line 261, in check\n",
      "  File \"/opt/homebrew/anaconda3/lib/python3.10/site-packages/IPython/extensions/autoreload.py\", line 484, in superreload\n",
      "  File \"/opt/homebrew/anaconda3/lib/python3.10/site-packages/IPython/extensions/autoreload.py\", line 381, in update_generic\n",
      "  File \"/opt/homebrew/anaconda3/lib/python3.10/site-packages/IPython/extensions/autoreload.py\", line 333, in update_class\n",
      "  File \"/opt/homebrew/anaconda3/lib/python3.10/site-packages/IPython/extensions/autoreload.py\", line 381, in update_generic\n",
      "  File \"/opt/homebrew/anaconda3/lib/python3.10/site-packages/IPython/extensions/autoreload.py\", line 293, in update_function\n",
      "ValueError: to_csv() requires a code object with 5 free vars, not 0\n",
      "]\n",
      "[autoreload of pandas.core.internals.construction failed: Traceback (most recent call last):\n",
      "  File \"/opt/homebrew/anaconda3/lib/python3.10/site-packages/IPython/extensions/autoreload.py\", line 261, in check\n",
      "  File \"/opt/homebrew/anaconda3/lib/python3.10/site-packages/IPython/extensions/autoreload.py\", line 459, in superreload\n",
      "  File \"/opt/homebrew/anaconda3/lib/python3.10/importlib/__init__.py\", line 169, in reload\n",
      "    _bootstrap._exec(spec, module)\n",
      "  File \"<frozen importlib._bootstrap>\", line 619, in _exec\n",
      "  File \"<frozen importlib._bootstrap_external>\", line 883, in exec_module\n",
      "  File \"<frozen importlib._bootstrap>\", line 241, in _call_with_frames_removed\n",
      "  File \"/opt/homebrew/anaconda3/lib/python3.10/site-packages/pandas/core/internals/construction.py\", line 20, in <module>\n",
      "    from pandas.core.dtypes.astype import astype_is_view\n",
      "ImportError: cannot import name 'astype_is_view' from 'pandas.core.dtypes.astype' (/opt/homebrew/anaconda3/lib/python3.10/site-packages/pandas/core/dtypes/astype.py)\n",
      "]\n",
      "[autoreload of pandas.core.window.rolling failed: Traceback (most recent call last):\n",
      "  File \"/opt/homebrew/anaconda3/lib/python3.10/site-packages/IPython/extensions/autoreload.py\", line 261, in check\n",
      "  File \"/opt/homebrew/anaconda3/lib/python3.10/site-packages/IPython/extensions/autoreload.py\", line 484, in superreload\n",
      "  File \"/opt/homebrew/anaconda3/lib/python3.10/site-packages/IPython/extensions/autoreload.py\", line 381, in update_generic\n",
      "  File \"/opt/homebrew/anaconda3/lib/python3.10/site-packages/IPython/extensions/autoreload.py\", line 333, in update_class\n",
      "  File \"/opt/homebrew/anaconda3/lib/python3.10/site-packages/IPython/extensions/autoreload.py\", line 381, in update_generic\n",
      "  File \"/opt/homebrew/anaconda3/lib/python3.10/site-packages/IPython/extensions/autoreload.py\", line 293, in update_function\n",
      "ValueError: quantile() requires a code object with 1 free vars, not 5\n",
      "]\n",
      "[autoreload of pandas.core.window.expanding failed: Traceback (most recent call last):\n",
      "  File \"/opt/homebrew/anaconda3/lib/python3.10/site-packages/IPython/extensions/autoreload.py\", line 261, in check\n",
      "  File \"/opt/homebrew/anaconda3/lib/python3.10/site-packages/IPython/extensions/autoreload.py\", line 484, in superreload\n",
      "  File \"/opt/homebrew/anaconda3/lib/python3.10/site-packages/IPython/extensions/autoreload.py\", line 381, in update_generic\n",
      "  File \"/opt/homebrew/anaconda3/lib/python3.10/site-packages/IPython/extensions/autoreload.py\", line 333, in update_class\n",
      "  File \"/opt/homebrew/anaconda3/lib/python3.10/site-packages/IPython/extensions/autoreload.py\", line 381, in update_generic\n",
      "  File \"/opt/homebrew/anaconda3/lib/python3.10/site-packages/IPython/extensions/autoreload.py\", line 293, in update_function\n",
      "ValueError: quantile() requires a code object with 1 free vars, not 5\n",
      "]\n",
      "[autoreload of pandas.core.generic failed: Traceback (most recent call last):\n",
      "  File \"/opt/homebrew/anaconda3/lib/python3.10/site-packages/IPython/extensions/autoreload.py\", line 261, in check\n",
      "  File \"/opt/homebrew/anaconda3/lib/python3.10/site-packages/IPython/extensions/autoreload.py\", line 459, in superreload\n",
      "  File \"/opt/homebrew/anaconda3/lib/python3.10/importlib/__init__.py\", line 169, in reload\n",
      "    _bootstrap._exec(spec, module)\n",
      "  File \"<frozen importlib._bootstrap>\", line 619, in _exec\n",
      "  File \"<frozen importlib._bootstrap_external>\", line 883, in exec_module\n",
      "  File \"<frozen importlib._bootstrap>\", line 241, in _call_with_frames_removed\n",
      "  File \"/opt/homebrew/anaconda3/lib/python3.10/site-packages/pandas/core/generic.py\", line 35, in <module>\n",
      "    from pandas._libs.lib import is_range_indexer\n",
      "ImportError: cannot import name 'is_range_indexer' from 'pandas._libs.lib' (/opt/homebrew/anaconda3/lib/python3.10/site-packages/pandas/_libs/lib.cpython-310-darwin.so)\n",
      "]\n",
      "[autoreload of pandas.core.tools.numeric failed: Traceback (most recent call last):\n",
      "  File \"/opt/homebrew/anaconda3/lib/python3.10/site-packages/IPython/extensions/autoreload.py\", line 261, in check\n",
      "  File \"/opt/homebrew/anaconda3/lib/python3.10/site-packages/IPython/extensions/autoreload.py\", line 459, in superreload\n",
      "  File \"/opt/homebrew/anaconda3/lib/python3.10/importlib/__init__.py\", line 169, in reload\n",
      "    _bootstrap._exec(spec, module)\n",
      "  File \"<frozen importlib._bootstrap>\", line 619, in _exec\n",
      "  File \"<frozen importlib._bootstrap_external>\", line 883, in exec_module\n",
      "  File \"<frozen importlib._bootstrap>\", line 241, in _call_with_frames_removed\n",
      "  File \"/opt/homebrew/anaconda3/lib/python3.10/site-packages/pandas/core/tools/numeric.py\", line 25, in <module>\n",
      "    from pandas.core.dtypes.dtypes import ArrowDtype\n",
      "ImportError: cannot import name 'ArrowDtype' from 'pandas.core.dtypes.dtypes' (/opt/homebrew/anaconda3/lib/python3.10/site-packages/pandas/core/dtypes/dtypes.py)\n",
      "]\n",
      "[autoreload of pandas.core.reshape.melt failed: Traceback (most recent call last):\n",
      "  File \"/opt/homebrew/anaconda3/lib/python3.10/site-packages/IPython/extensions/autoreload.py\", line 261, in check\n",
      "  File \"/opt/homebrew/anaconda3/lib/python3.10/site-packages/IPython/extensions/autoreload.py\", line 484, in superreload\n",
      "  File \"/opt/homebrew/anaconda3/lib/python3.10/site-packages/IPython/extensions/autoreload.py\", line 381, in update_generic\n",
      "  File \"/opt/homebrew/anaconda3/lib/python3.10/site-packages/IPython/extensions/autoreload.py\", line 293, in update_function\n",
      "ValueError: lreshape() requires a code object with 5 free vars, not 0\n",
      "]\n",
      "[autoreload of pandas.core.indexes.accessors failed: Traceback (most recent call last):\n",
      "  File \"/opt/homebrew/anaconda3/lib/python3.10/site-packages/IPython/extensions/autoreload.py\", line 261, in check\n",
      "  File \"/opt/homebrew/anaconda3/lib/python3.10/site-packages/IPython/extensions/autoreload.py\", line 459, in superreload\n",
      "  File \"/opt/homebrew/anaconda3/lib/python3.10/importlib/__init__.py\", line 169, in reload\n",
      "    _bootstrap._exec(spec, module)\n",
      "  File \"<frozen importlib._bootstrap>\", line 619, in _exec\n",
      "  File \"<frozen importlib._bootstrap_external>\", line 883, in exec_module\n",
      "  File \"<frozen importlib._bootstrap>\", line 241, in _call_with_frames_removed\n",
      "  File \"/opt/homebrew/anaconda3/lib/python3.10/site-packages/pandas/core/indexes/accessors.py\", line 21, in <module>\n",
      "    from pandas.core.dtypes.dtypes import (\n",
      "ImportError: cannot import name 'ArrowDtype' from 'pandas.core.dtypes.dtypes' (/opt/homebrew/anaconda3/lib/python3.10/site-packages/pandas/core/dtypes/dtypes.py)\n",
      "]\n",
      "[autoreload of pandas.arrays failed: Traceback (most recent call last):\n",
      "  File \"/opt/homebrew/anaconda3/lib/python3.10/site-packages/IPython/extensions/autoreload.py\", line 261, in check\n",
      "  File \"/opt/homebrew/anaconda3/lib/python3.10/site-packages/IPython/extensions/autoreload.py\", line 459, in superreload\n",
      "  File \"/opt/homebrew/anaconda3/lib/python3.10/importlib/__init__.py\", line 169, in reload\n",
      "    _bootstrap._exec(spec, module)\n",
      "  File \"<frozen importlib._bootstrap>\", line 619, in _exec\n",
      "  File \"<frozen importlib._bootstrap_external>\", line 883, in exec_module\n",
      "  File \"<frozen importlib._bootstrap>\", line 241, in _call_with_frames_removed\n",
      "  File \"/opt/homebrew/anaconda3/lib/python3.10/site-packages/pandas/arrays/__init__.py\", line 6, in <module>\n",
      "    from pandas.core.arrays import (\n",
      "ImportError: cannot import name 'NumpyExtensionArray' from 'pandas.core.arrays' (/opt/homebrew/anaconda3/lib/python3.10/site-packages/pandas/core/arrays/__init__.py)\n",
      "]\n",
      "[autoreload of pandas.core.tools.datetimes failed: Traceback (most recent call last):\n",
      "  File \"/opt/homebrew/anaconda3/lib/python3.10/site-packages/IPython/extensions/autoreload.py\", line 261, in check\n",
      "  File \"/opt/homebrew/anaconda3/lib/python3.10/site-packages/IPython/extensions/autoreload.py\", line 459, in superreload\n",
      "  File \"/opt/homebrew/anaconda3/lib/python3.10/importlib/__init__.py\", line 169, in reload\n",
      "    _bootstrap._exec(spec, module)\n",
      "  File \"<frozen importlib._bootstrap>\", line 619, in _exec\n",
      "  File \"<frozen importlib._bootstrap_external>\", line 883, in exec_module\n",
      "  File \"<frozen importlib._bootstrap>\", line 241, in _call_with_frames_removed\n",
      "  File \"/opt/homebrew/anaconda3/lib/python3.10/site-packages/pandas/core/tools/datetimes.py\", line 57, in <module>\n",
      "    from pandas.core.dtypes.dtypes import (\n",
      "ImportError: cannot import name 'ArrowDtype' from 'pandas.core.dtypes.dtypes' (/opt/homebrew/anaconda3/lib/python3.10/site-packages/pandas/core/dtypes/dtypes.py)\n",
      "]\n",
      "[autoreload of pandas.core.series failed: Traceback (most recent call last):\n",
      "  File \"/opt/homebrew/anaconda3/lib/python3.10/site-packages/IPython/extensions/autoreload.py\", line 261, in check\n",
      "  File \"/opt/homebrew/anaconda3/lib/python3.10/site-packages/IPython/extensions/autoreload.py\", line 459, in superreload\n",
      "  File \"/opt/homebrew/anaconda3/lib/python3.10/importlib/__init__.py\", line 169, in reload\n",
      "    _bootstrap._exec(spec, module)\n",
      "  File \"<frozen importlib._bootstrap>\", line 619, in _exec\n",
      "  File \"<frozen importlib._bootstrap_external>\", line 883, in exec_module\n",
      "  File \"<frozen importlib._bootstrap>\", line 241, in _call_with_frames_removed\n",
      "  File \"/opt/homebrew/anaconda3/lib/python3.10/site-packages/pandas/core/series.py\", line 39, in <module>\n",
      "    from pandas._libs.lib import is_range_indexer\n",
      "ImportError: cannot import name 'is_range_indexer' from 'pandas._libs.lib' (/opt/homebrew/anaconda3/lib/python3.10/site-packages/pandas/_libs/lib.cpython-310-darwin.so)\n",
      "]\n",
      "[autoreload of pandas.core.frame failed: Traceback (most recent call last):\n",
      "  File \"/opt/homebrew/anaconda3/lib/python3.10/site-packages/IPython/extensions/autoreload.py\", line 261, in check\n",
      "  File \"/opt/homebrew/anaconda3/lib/python3.10/site-packages/IPython/extensions/autoreload.py\", line 459, in superreload\n",
      "  File \"/opt/homebrew/anaconda3/lib/python3.10/importlib/__init__.py\", line 169, in reload\n",
      "    _bootstrap._exec(spec, module)\n",
      "  File \"<frozen importlib._bootstrap>\", line 619, in _exec\n",
      "  File \"<frozen importlib._bootstrap_external>\", line 883, in exec_module\n",
      "  File \"<frozen importlib._bootstrap>\", line 241, in _call_with_frames_removed\n",
      "  File \"/opt/homebrew/anaconda3/lib/python3.10/site-packages/pandas/core/frame.py\", line 53, in <module>\n",
      "    from pandas._libs.lib import is_range_indexer\n",
      "ImportError: cannot import name 'is_range_indexer' from 'pandas._libs.lib' (/opt/homebrew/anaconda3/lib/python3.10/site-packages/pandas/_libs/lib.cpython-310-darwin.so)\n",
      "]\n",
      "[autoreload of pandas.core.groupby.generic failed: Traceback (most recent call last):\n",
      "  File \"/opt/homebrew/anaconda3/lib/python3.10/site-packages/IPython/extensions/autoreload.py\", line 261, in check\n",
      "  File \"/opt/homebrew/anaconda3/lib/python3.10/site-packages/IPython/extensions/autoreload.py\", line 484, in superreload\n",
      "  File \"/opt/homebrew/anaconda3/lib/python3.10/site-packages/IPython/extensions/autoreload.py\", line 381, in update_generic\n",
      "  File \"/opt/homebrew/anaconda3/lib/python3.10/site-packages/IPython/extensions/autoreload.py\", line 333, in update_class\n",
      "  File \"/opt/homebrew/anaconda3/lib/python3.10/site-packages/IPython/extensions/autoreload.py\", line 381, in update_generic\n",
      "  File \"/opt/homebrew/anaconda3/lib/python3.10/site-packages/IPython/extensions/autoreload.py\", line 355, in update_property\n",
      "  File \"/opt/homebrew/anaconda3/lib/python3.10/site-packages/IPython/extensions/autoreload.py\", line 381, in update_generic\n",
      "  File \"/opt/homebrew/anaconda3/lib/python3.10/site-packages/IPython/extensions/autoreload.py\", line 293, in update_function\n",
      "ValueError: is_monotonic_increasing() requires a code object with 1 free vars, not 0\n",
      "]\n",
      "[autoreload of pandas.core.api failed: Traceback (most recent call last):\n",
      "  File \"/opt/homebrew/anaconda3/lib/python3.10/site-packages/IPython/extensions/autoreload.py\", line 261, in check\n",
      "  File \"/opt/homebrew/anaconda3/lib/python3.10/site-packages/IPython/extensions/autoreload.py\", line 459, in superreload\n",
      "  File \"/opt/homebrew/anaconda3/lib/python3.10/importlib/__init__.py\", line 169, in reload\n",
      "    _bootstrap._exec(spec, module)\n",
      "  File \"<frozen importlib._bootstrap>\", line 619, in _exec\n",
      "  File \"<frozen importlib._bootstrap_external>\", line 883, in exec_module\n",
      "  File \"<frozen importlib._bootstrap>\", line 241, in _call_with_frames_removed\n",
      "  File \"/opt/homebrew/anaconda3/lib/python3.10/site-packages/pandas/core/api.py\", line 9, in <module>\n",
      "    from pandas.core.dtypes.dtypes import (\n",
      "ImportError: cannot import name 'ArrowDtype' from 'pandas.core.dtypes.dtypes' (/opt/homebrew/anaconda3/lib/python3.10/site-packages/pandas/core/dtypes/dtypes.py)\n",
      "]\n",
      "[autoreload of pandas.core.computation.ops failed: Traceback (most recent call last):\n",
      "  File \"/opt/homebrew/anaconda3/lib/python3.10/site-packages/IPython/extensions/autoreload.py\", line 261, in check\n",
      "  File \"/opt/homebrew/anaconda3/lib/python3.10/site-packages/IPython/extensions/autoreload.py\", line 484, in superreload\n",
      "  File \"/opt/homebrew/anaconda3/lib/python3.10/site-packages/IPython/extensions/autoreload.py\", line 381, in update_generic\n",
      "  File \"/opt/homebrew/anaconda3/lib/python3.10/site-packages/IPython/extensions/autoreload.py\", line 333, in update_class\n",
      "  File \"/opt/homebrew/anaconda3/lib/python3.10/site-packages/IPython/extensions/autoreload.py\", line 381, in update_generic\n",
      "  File \"/opt/homebrew/anaconda3/lib/python3.10/site-packages/IPython/extensions/autoreload.py\", line 293, in update_function\n",
      "ValueError: __init__() requires a code object with 1 free vars, not 0\n",
      "]\n",
      "[autoreload of pandas.core.computation.expr failed: Traceback (most recent call last):\n",
      "  File \"/opt/homebrew/anaconda3/lib/python3.10/site-packages/IPython/extensions/autoreload.py\", line 261, in check\n",
      "  File \"/opt/homebrew/anaconda3/lib/python3.10/site-packages/IPython/extensions/autoreload.py\", line 484, in superreload\n",
      "  File \"/opt/homebrew/anaconda3/lib/python3.10/site-packages/IPython/extensions/autoreload.py\", line 381, in update_generic\n",
      "  File \"/opt/homebrew/anaconda3/lib/python3.10/site-packages/IPython/extensions/autoreload.py\", line 333, in update_class\n",
      "  File \"/opt/homebrew/anaconda3/lib/python3.10/site-packages/IPython/extensions/autoreload.py\", line 381, in update_generic\n",
      "  File \"/opt/homebrew/anaconda3/lib/python3.10/site-packages/IPython/extensions/autoreload.py\", line 333, in update_class\n",
      "  File \"/opt/homebrew/anaconda3/lib/python3.10/site-packages/IPython/extensions/autoreload.py\", line 381, in update_generic\n",
      "  File \"/opt/homebrew/anaconda3/lib/python3.10/site-packages/IPython/extensions/autoreload.py\", line 293, in update_function\n",
      "ValueError: __init__() requires a code object with 1 free vars, not 0\n",
      "]\n",
      "[autoreload of pandas.core.reshape.merge failed: Traceback (most recent call last):\n",
      "  File \"/opt/homebrew/anaconda3/lib/python3.10/site-packages/IPython/extensions/autoreload.py\", line 261, in check\n",
      "  File \"/opt/homebrew/anaconda3/lib/python3.10/site-packages/IPython/extensions/autoreload.py\", line 459, in superreload\n",
      "  File \"/opt/homebrew/anaconda3/lib/python3.10/importlib/__init__.py\", line 169, in reload\n",
      "    _bootstrap._exec(spec, module)\n",
      "  File \"<frozen importlib._bootstrap>\", line 619, in _exec\n",
      "  File \"<frozen importlib._bootstrap_external>\", line 883, in exec_module\n",
      "  File \"<frozen importlib._bootstrap>\", line 241, in _call_with_frames_removed\n",
      "  File \"/opt/homebrew/anaconda3/lib/python3.10/site-packages/pandas/core/reshape/merge.py\", line 30, in <module>\n",
      "    from pandas._libs.lib import is_range_indexer\n",
      "ImportError: cannot import name 'is_range_indexer' from 'pandas._libs.lib' (/opt/homebrew/anaconda3/lib/python3.10/site-packages/pandas/_libs/lib.cpython-310-darwin.so)\n",
      "]\n",
      "[autoreload of pandas.core.reshape.pivot failed: Traceback (most recent call last):\n",
      "  File \"/opt/homebrew/anaconda3/lib/python3.10/site-packages/IPython/extensions/autoreload.py\", line 261, in check\n",
      "  File \"/opt/homebrew/anaconda3/lib/python3.10/site-packages/IPython/extensions/autoreload.py\", line 484, in superreload\n",
      "  File \"/opt/homebrew/anaconda3/lib/python3.10/site-packages/IPython/extensions/autoreload.py\", line 381, in update_generic\n",
      "  File \"/opt/homebrew/anaconda3/lib/python3.10/site-packages/IPython/extensions/autoreload.py\", line 293, in update_function\n",
      "ValueError: pivot() requires a code object with 4 free vars, not 0\n",
      "]\n",
      "[autoreload of pandas.core.dtypes.api failed: Traceback (most recent call last):\n",
      "  File \"/opt/homebrew/anaconda3/lib/python3.10/site-packages/IPython/extensions/autoreload.py\", line 261, in check\n",
      "  File \"/opt/homebrew/anaconda3/lib/python3.10/site-packages/IPython/extensions/autoreload.py\", line 459, in superreload\n",
      "  File \"/opt/homebrew/anaconda3/lib/python3.10/importlib/__init__.py\", line 169, in reload\n",
      "    _bootstrap._exec(spec, module)\n",
      "  File \"<frozen importlib._bootstrap>\", line 619, in _exec\n",
      "  File \"<frozen importlib._bootstrap_external>\", line 883, in exec_module\n",
      "  File \"<frozen importlib._bootstrap>\", line 241, in _call_with_frames_removed\n",
      "  File \"/opt/homebrew/anaconda3/lib/python3.10/site-packages/pandas/core/dtypes/api.py\", line 1, in <module>\n",
      "    from pandas.core.dtypes.common import (\n",
      "ImportError: cannot import name 'is_any_real_numeric_dtype' from 'pandas.core.dtypes.common' (/opt/homebrew/anaconda3/lib/python3.10/site-packages/pandas/core/dtypes/common.py)\n",
      "]\n",
      "[autoreload of pandas.core.interchange.utils failed: Traceback (most recent call last):\n",
      "  File \"/opt/homebrew/anaconda3/lib/python3.10/site-packages/IPython/extensions/autoreload.py\", line 261, in check\n",
      "  File \"/opt/homebrew/anaconda3/lib/python3.10/site-packages/IPython/extensions/autoreload.py\", line 459, in superreload\n",
      "  File \"/opt/homebrew/anaconda3/lib/python3.10/importlib/__init__.py\", line 169, in reload\n",
      "    _bootstrap._exec(spec, module)\n",
      "  File \"<frozen importlib._bootstrap>\", line 619, in _exec\n",
      "  File \"<frozen importlib._bootstrap_external>\", line 883, in exec_module\n",
      "  File \"<frozen importlib._bootstrap>\", line 241, in _call_with_frames_removed\n",
      "  File \"/opt/homebrew/anaconda3/lib/python3.10/site-packages/pandas/core/interchange/utils.py\", line 13, in <module>\n",
      "    from pandas.core.dtypes.dtypes import (\n",
      "ImportError: cannot import name 'ArrowDtype' from 'pandas.core.dtypes.dtypes' (/opt/homebrew/anaconda3/lib/python3.10/site-packages/pandas/core/dtypes/dtypes.py)\n",
      "]\n",
      "[autoreload of pandas.core.interchange.column failed: Traceback (most recent call last):\n",
      "  File \"/opt/homebrew/anaconda3/lib/python3.10/site-packages/IPython/extensions/autoreload.py\", line 261, in check\n",
      "  File \"/opt/homebrew/anaconda3/lib/python3.10/site-packages/IPython/extensions/autoreload.py\", line 459, in superreload\n",
      "  File \"/opt/homebrew/anaconda3/lib/python3.10/importlib/__init__.py\", line 169, in reload\n",
      "    _bootstrap._exec(spec, module)\n",
      "  File \"<frozen importlib._bootstrap>\", line 619, in _exec\n",
      "  File \"<frozen importlib._bootstrap_external>\", line 883, in exec_module\n",
      "  File \"<frozen importlib._bootstrap>\", line 241, in _call_with_frames_removed\n",
      "  File \"/opt/homebrew/anaconda3/lib/python3.10/site-packages/pandas/core/interchange/column.py\", line 12, in <module>\n",
      "    from pandas.core.dtypes.dtypes import (\n",
      "ImportError: cannot import name 'ArrowDtype' from 'pandas.core.dtypes.dtypes' (/opt/homebrew/anaconda3/lib/python3.10/site-packages/pandas/core/dtypes/dtypes.py)\n",
      "]\n",
      "[autoreload of pandas._testing.asserters failed: Traceback (most recent call last):\n",
      "  File \"/opt/homebrew/anaconda3/lib/python3.10/site-packages/IPython/extensions/autoreload.py\", line 261, in check\n",
      "  File \"/opt/homebrew/anaconda3/lib/python3.10/site-packages/IPython/extensions/autoreload.py\", line 459, in superreload\n",
      "  File \"/opt/homebrew/anaconda3/lib/python3.10/importlib/__init__.py\", line 169, in reload\n",
      "    _bootstrap._exec(spec, module)\n",
      "  File \"<frozen importlib._bootstrap>\", line 619, in _exec\n",
      "  File \"<frozen importlib._bootstrap_external>\", line 883, in exec_module\n",
      "  File \"<frozen importlib._bootstrap>\", line 241, in _call_with_frames_removed\n",
      "  File \"/opt/homebrew/anaconda3/lib/python3.10/site-packages/pandas/_testing/asserters.py\", line 24, in <module>\n",
      "    from pandas.core.dtypes.dtypes import (\n",
      "ImportError: cannot import name 'NumpyEADtype' from 'pandas.core.dtypes.dtypes' (/opt/homebrew/anaconda3/lib/python3.10/site-packages/pandas/core/dtypes/dtypes.py)\n",
      "]\n",
      "[autoreload of pandas._testing failed: Traceback (most recent call last):\n",
      "  File \"/opt/homebrew/anaconda3/lib/python3.10/site-packages/IPython/extensions/autoreload.py\", line 261, in check\n",
      "  File \"/opt/homebrew/anaconda3/lib/python3.10/site-packages/IPython/extensions/autoreload.py\", line 459, in superreload\n",
      "  File \"/opt/homebrew/anaconda3/lib/python3.10/importlib/__init__.py\", line 169, in reload\n",
      "    _bootstrap._exec(spec, module)\n",
      "  File \"<frozen importlib._bootstrap>\", line 619, in _exec\n",
      "  File \"<frozen importlib._bootstrap_external>\", line 883, in exec_module\n",
      "  File \"<frozen importlib._bootstrap>\", line 241, in _call_with_frames_removed\n",
      "  File \"/opt/homebrew/anaconda3/lib/python3.10/site-packages/pandas/_testing/__init__.py\", line 98, in <module>\n",
      "    from pandas.core.arrays import (\n",
      "ImportError: cannot import name 'NumpyExtensionArray' from 'pandas.core.arrays' (/opt/homebrew/anaconda3/lib/python3.10/site-packages/pandas/core/arrays/__init__.py)\n",
      "]\n",
      "[autoreload of pandas.io.parsers.readers failed: Traceback (most recent call last):\n",
      "  File \"/opt/homebrew/anaconda3/lib/python3.10/site-packages/IPython/extensions/autoreload.py\", line 261, in check\n",
      "  File \"/opt/homebrew/anaconda3/lib/python3.10/site-packages/IPython/extensions/autoreload.py\", line 484, in superreload\n",
      "  File \"/opt/homebrew/anaconda3/lib/python3.10/site-packages/IPython/extensions/autoreload.py\", line 381, in update_generic\n",
      "  File \"/opt/homebrew/anaconda3/lib/python3.10/site-packages/IPython/extensions/autoreload.py\", line 293, in update_function\n",
      "ValueError: read_csv() requires a code object with 5 free vars, not 0\n",
      "]\n",
      "[autoreload of pandas.io.excel._odfreader failed: Traceback (most recent call last):\n",
      "  File \"/opt/homebrew/anaconda3/lib/python3.10/site-packages/IPython/extensions/autoreload.py\", line 261, in check\n",
      "  File \"/opt/homebrew/anaconda3/lib/python3.10/site-packages/IPython/extensions/autoreload.py\", line 459, in superreload\n",
      "  File \"/opt/homebrew/anaconda3/lib/python3.10/importlib/__init__.py\", line 169, in reload\n",
      "    _bootstrap._exec(spec, module)\n",
      "  File \"<frozen importlib._bootstrap>\", line 619, in _exec\n",
      "  File \"<frozen importlib._bootstrap_external>\", line 883, in exec_module\n",
      "  File \"<frozen importlib._bootstrap>\", line 241, in _call_with_frames_removed\n",
      "  File \"/opt/homebrew/anaconda3/lib/python3.10/site-packages/pandas/io/excel/_odfreader.py\", line 31, in <module>\n",
      "    class ODFReader(BaseExcelReader[\"OpenDocument\"]):\n",
      "TypeError: 'ABCMeta' object is not subscriptable\n",
      "]\n",
      "[autoreload of pandas.io.excel._openpyxl failed: Traceback (most recent call last):\n",
      "  File \"/opt/homebrew/anaconda3/lib/python3.10/site-packages/IPython/extensions/autoreload.py\", line 261, in check\n",
      "  File \"/opt/homebrew/anaconda3/lib/python3.10/site-packages/IPython/extensions/autoreload.py\", line 459, in superreload\n",
      "  File \"/opt/homebrew/anaconda3/lib/python3.10/importlib/__init__.py\", line 169, in reload\n",
      "    _bootstrap._exec(spec, module)\n",
      "  File \"<frozen importlib._bootstrap>\", line 619, in _exec\n",
      "  File \"<frozen importlib._bootstrap_external>\", line 883, in exec_module\n",
      "  File \"<frozen importlib._bootstrap>\", line 241, in _call_with_frames_removed\n",
      "  File \"/opt/homebrew/anaconda3/lib/python3.10/site-packages/pandas/io/excel/_openpyxl.py\", line 533, in <module>\n",
      "    class OpenpyxlReader(BaseExcelReader[\"Workbook\"]):\n",
      "TypeError: 'ABCMeta' object is not subscriptable\n",
      "]\n",
      "[autoreload of pandas.io.excel._pyxlsb failed: Traceback (most recent call last):\n",
      "  File \"/opt/homebrew/anaconda3/lib/python3.10/site-packages/IPython/extensions/autoreload.py\", line 261, in check\n",
      "  File \"/opt/homebrew/anaconda3/lib/python3.10/site-packages/IPython/extensions/autoreload.py\", line 459, in superreload\n",
      "  File \"/opt/homebrew/anaconda3/lib/python3.10/importlib/__init__.py\", line 169, in reload\n",
      "    _bootstrap._exec(spec, module)\n",
      "  File \"<frozen importlib._bootstrap>\", line 619, in _exec\n",
      "  File \"<frozen importlib._bootstrap_external>\", line 883, in exec_module\n",
      "  File \"<frozen importlib._bootstrap>\", line 241, in _call_with_frames_removed\n",
      "  File \"/opt/homebrew/anaconda3/lib/python3.10/site-packages/pandas/io/excel/_pyxlsb.py\", line 24, in <module>\n",
      "    class PyxlsbReader(BaseExcelReader[\"Workbook\"]):\n",
      "TypeError: 'ABCMeta' object is not subscriptable\n",
      "]\n",
      "[autoreload of pandas.io.excel._xlrd failed: Traceback (most recent call last):\n",
      "  File \"/opt/homebrew/anaconda3/lib/python3.10/site-packages/IPython/extensions/autoreload.py\", line 261, in check\n",
      "  File \"/opt/homebrew/anaconda3/lib/python3.10/site-packages/IPython/extensions/autoreload.py\", line 459, in superreload\n",
      "  File \"/opt/homebrew/anaconda3/lib/python3.10/importlib/__init__.py\", line 169, in reload\n",
      "    _bootstrap._exec(spec, module)\n",
      "  File \"<frozen importlib._bootstrap>\", line 619, in _exec\n",
      "  File \"<frozen importlib._bootstrap_external>\", line 883, in exec_module\n",
      "  File \"<frozen importlib._bootstrap>\", line 241, in _call_with_frames_removed\n",
      "  File \"/opt/homebrew/anaconda3/lib/python3.10/site-packages/pandas/io/excel/_xlrd.py\", line 24, in <module>\n",
      "    class XlrdReader(BaseExcelReader[\"Book\"]):\n",
      "TypeError: 'ABCMeta' object is not subscriptable\n",
      "]\n",
      "[autoreload of pandas.io.excel._base failed: Traceback (most recent call last):\n",
      "  File \"/opt/homebrew/anaconda3/lib/python3.10/site-packages/IPython/extensions/autoreload.py\", line 261, in check\n",
      "  File \"/opt/homebrew/anaconda3/lib/python3.10/site-packages/IPython/extensions/autoreload.py\", line 484, in superreload\n",
      "  File \"/opt/homebrew/anaconda3/lib/python3.10/site-packages/IPython/extensions/autoreload.py\", line 381, in update_generic\n",
      "  File \"/opt/homebrew/anaconda3/lib/python3.10/site-packages/IPython/extensions/autoreload.py\", line 293, in update_function\n",
      "ValueError: read_excel() requires a code object with 5 free vars, not 0\n",
      "]\n",
      "[autoreload of pandas.io.html failed: Traceback (most recent call last):\n",
      "  File \"/opt/homebrew/anaconda3/lib/python3.10/site-packages/IPython/extensions/autoreload.py\", line 261, in check\n",
      "  File \"/opt/homebrew/anaconda3/lib/python3.10/site-packages/IPython/extensions/autoreload.py\", line 484, in superreload\n",
      "  File \"/opt/homebrew/anaconda3/lib/python3.10/site-packages/IPython/extensions/autoreload.py\", line 381, in update_generic\n",
      "  File \"/opt/homebrew/anaconda3/lib/python3.10/site-packages/IPython/extensions/autoreload.py\", line 293, in update_function\n",
      "ValueError: read_html() requires a code object with 4 free vars, not 0\n",
      "]\n",
      "[autoreload of pandas.io.json._normalize failed: Traceback (most recent call last):\n",
      "  File \"/opt/homebrew/anaconda3/lib/python3.10/site-packages/IPython/extensions/autoreload.py\", line 261, in check\n",
      "  File \"/opt/homebrew/anaconda3/lib/python3.10/site-packages/IPython/extensions/autoreload.py\", line 484, in superreload\n",
      "  File \"/opt/homebrew/anaconda3/lib/python3.10/site-packages/IPython/extensions/autoreload.py\", line 381, in update_generic\n",
      "  File \"/opt/homebrew/anaconda3/lib/python3.10/site-packages/IPython/extensions/autoreload.py\", line 293, in update_function\n",
      "ValueError: _json_normalize() requires a code object with 4 free vars, not 0\n",
      "]\n",
      "[autoreload of pandas.io.json._table_schema failed: Traceback (most recent call last):\n",
      "  File \"/opt/homebrew/anaconda3/lib/python3.10/site-packages/IPython/extensions/autoreload.py\", line 261, in check\n",
      "  File \"/opt/homebrew/anaconda3/lib/python3.10/site-packages/IPython/extensions/autoreload.py\", line 459, in superreload\n",
      "  File \"/opt/homebrew/anaconda3/lib/python3.10/importlib/__init__.py\", line 169, in reload\n",
      "    _bootstrap._exec(spec, module)\n",
      "  File \"<frozen importlib._bootstrap>\", line 619, in _exec\n",
      "  File \"<frozen importlib._bootstrap_external>\", line 883, in exec_module\n",
      "  File \"<frozen importlib._bootstrap>\", line 241, in _call_with_frames_removed\n",
      "  File \"/opt/homebrew/anaconda3/lib/python3.10/site-packages/pandas/io/json/_table_schema.py\", line 16, in <module>\n",
      "    from pandas._libs.json import ujson_loads\n",
      "ImportError: cannot import name 'ujson_loads' from 'pandas._libs.json' (/opt/homebrew/anaconda3/lib/python3.10/site-packages/pandas/_libs/json.cpython-310-darwin.so)\n",
      "]\n",
      "[autoreload of pandas.io.json._json failed: Traceback (most recent call last):\n",
      "  File \"/opt/homebrew/anaconda3/lib/python3.10/site-packages/IPython/extensions/autoreload.py\", line 261, in check\n",
      "  File \"/opt/homebrew/anaconda3/lib/python3.10/site-packages/IPython/extensions/autoreload.py\", line 459, in superreload\n",
      "  File \"/opt/homebrew/anaconda3/lib/python3.10/importlib/__init__.py\", line 169, in reload\n",
      "    _bootstrap._exec(spec, module)\n",
      "  File \"<frozen importlib._bootstrap>\", line 619, in _exec\n",
      "  File \"<frozen importlib._bootstrap_external>\", line 883, in exec_module\n",
      "  File \"<frozen importlib._bootstrap>\", line 241, in _call_with_frames_removed\n",
      "  File \"/opt/homebrew/anaconda3/lib/python3.10/site-packages/pandas/io/json/_json.py\", line 24, in <module>\n",
      "    from pandas._libs.json import (\n",
      "ImportError: cannot import name 'ujson_dumps' from 'pandas._libs.json' (/opt/homebrew/anaconda3/lib/python3.10/site-packages/pandas/_libs/json.cpython-310-darwin.so)\n",
      "]\n",
      "[autoreload of pandas.io.json failed: Traceback (most recent call last):\n",
      "  File \"/opt/homebrew/anaconda3/lib/python3.10/site-packages/IPython/extensions/autoreload.py\", line 261, in check\n",
      "  File \"/opt/homebrew/anaconda3/lib/python3.10/site-packages/IPython/extensions/autoreload.py\", line 459, in superreload\n",
      "  File \"/opt/homebrew/anaconda3/lib/python3.10/importlib/__init__.py\", line 169, in reload\n",
      "    _bootstrap._exec(spec, module)\n",
      "  File \"<frozen importlib._bootstrap>\", line 619, in _exec\n",
      "  File \"<frozen importlib._bootstrap_external>\", line 883, in exec_module\n",
      "  File \"<frozen importlib._bootstrap>\", line 241, in _call_with_frames_removed\n",
      "  File \"/opt/homebrew/anaconda3/lib/python3.10/site-packages/pandas/io/json/__init__.py\", line 1, in <module>\n",
      "    from pandas.io.json._json import (\n",
      "ImportError: cannot import name 'ujson_dumps' from 'pandas.io.json._json' (/opt/homebrew/anaconda3/lib/python3.10/site-packages/pandas/io/json/_json.py)\n",
      "]\n"
     ]
    },
    {
     "name": "stdout",
     "output_type": "stream",
     "text": [
      "1.5.3\n"
     ]
    },
    {
     "name": "stderr",
     "output_type": "stream",
     "text": [
      "[autoreload of pandas.io.sas.sasreader failed: Traceback (most recent call last):\n",
      "  File \"/opt/homebrew/anaconda3/lib/python3.10/site-packages/IPython/extensions/autoreload.py\", line 261, in check\n",
      "  File \"/opt/homebrew/anaconda3/lib/python3.10/site-packages/IPython/extensions/autoreload.py\", line 484, in superreload\n",
      "  File \"/opt/homebrew/anaconda3/lib/python3.10/site-packages/IPython/extensions/autoreload.py\", line 381, in update_generic\n",
      "  File \"/opt/homebrew/anaconda3/lib/python3.10/site-packages/IPython/extensions/autoreload.py\", line 293, in update_function\n",
      "ValueError: read_sas() requires a code object with 4 free vars, not 0\n",
      "]\n",
      "[autoreload of pandas.io.sql failed: Traceback (most recent call last):\n",
      "  File \"/opt/homebrew/anaconda3/lib/python3.10/site-packages/IPython/extensions/autoreload.py\", line 261, in check\n",
      "  File \"/opt/homebrew/anaconda3/lib/python3.10/site-packages/IPython/extensions/autoreload.py\", line 459, in superreload\n",
      "  File \"/opt/homebrew/anaconda3/lib/python3.10/importlib/__init__.py\", line 169, in reload\n",
      "    _bootstrap._exec(spec, module)\n",
      "  File \"<frozen importlib._bootstrap>\", line 619, in _exec\n",
      "  File \"<frozen importlib._bootstrap_external>\", line 883, in exec_module\n",
      "  File \"<frozen importlib._bootstrap>\", line 241, in _call_with_frames_removed\n",
      "  File \"/opt/homebrew/anaconda3/lib/python3.10/site-packages/pandas/io/sql.py\", line 59, in <module>\n",
      "    from pandas.core.internals.construction import convert_object_array\n",
      "ImportError: cannot import name 'convert_object_array' from 'pandas.core.internals.construction' (/opt/homebrew/anaconda3/lib/python3.10/site-packages/pandas/core/internals/construction.py)\n",
      "]\n",
      "[autoreload of pandas.io.stata failed: Traceback (most recent call last):\n",
      "  File \"/opt/homebrew/anaconda3/lib/python3.10/site-packages/IPython/extensions/autoreload.py\", line 261, in check\n",
      "  File \"/opt/homebrew/anaconda3/lib/python3.10/site-packages/IPython/extensions/autoreload.py\", line 484, in superreload\n",
      "  File \"/opt/homebrew/anaconda3/lib/python3.10/site-packages/IPython/extensions/autoreload.py\", line 381, in update_generic\n",
      "  File \"/opt/homebrew/anaconda3/lib/python3.10/site-packages/IPython/extensions/autoreload.py\", line 293, in update_function\n",
      "ValueError: read_stata() requires a code object with 4 free vars, not 0\n",
      "]\n",
      "[autoreload of pandas.io.xml failed: Traceback (most recent call last):\n",
      "  File \"/opt/homebrew/anaconda3/lib/python3.10/site-packages/IPython/extensions/autoreload.py\", line 261, in check\n",
      "  File \"/opt/homebrew/anaconda3/lib/python3.10/site-packages/IPython/extensions/autoreload.py\", line 484, in superreload\n",
      "  File \"/opt/homebrew/anaconda3/lib/python3.10/site-packages/IPython/extensions/autoreload.py\", line 381, in update_generic\n",
      "  File \"/opt/homebrew/anaconda3/lib/python3.10/site-packages/IPython/extensions/autoreload.py\", line 293, in update_function\n",
      "ValueError: read_xml() requires a code object with 4 free vars, not 0\n",
      "]\n",
      "[autoreload of pandas failed: Traceback (most recent call last):\n",
      "  File \"/opt/homebrew/anaconda3/lib/python3.10/site-packages/IPython/extensions/autoreload.py\", line 261, in check\n",
      "  File \"/opt/homebrew/anaconda3/lib/python3.10/site-packages/IPython/extensions/autoreload.py\", line 459, in superreload\n",
      "  File \"/opt/homebrew/anaconda3/lib/python3.10/importlib/__init__.py\", line 169, in reload\n",
      "    _bootstrap._exec(spec, module)\n",
      "  File \"<frozen importlib._bootstrap>\", line 619, in _exec\n",
      "  File \"<frozen importlib._bootstrap_external>\", line 883, in exec_module\n",
      "  File \"<frozen importlib._bootstrap>\", line 241, in _call_with_frames_removed\n",
      "  File \"/opt/homebrew/anaconda3/lib/python3.10/site-packages/pandas/__init__.py\", line 111, in <module>\n",
      "    from pandas.core.dtypes.dtypes import SparseDtype\n",
      "ImportError: cannot import name 'SparseDtype' from 'pandas.core.dtypes.dtypes' (/opt/homebrew/anaconda3/lib/python3.10/site-packages/pandas/core/dtypes/dtypes.py)\n",
      "]\n",
      "[autoreload of numpy.testing._private.utils failed: Traceback (most recent call last):\n",
      "  File \"/opt/homebrew/anaconda3/lib/python3.10/site-packages/IPython/extensions/autoreload.py\", line 261, in check\n",
      "  File \"/opt/homebrew/anaconda3/lib/python3.10/site-packages/IPython/extensions/autoreload.py\", line 459, in superreload\n",
      "  File \"/opt/homebrew/anaconda3/lib/python3.10/importlib/__init__.py\", line 169, in reload\n",
      "    _bootstrap._exec(spec, module)\n",
      "  File \"<frozen importlib._bootstrap>\", line 619, in _exec\n",
      "  File \"<frozen importlib._bootstrap_external>\", line 883, in exec_module\n",
      "  File \"<frozen importlib._bootstrap>\", line 241, in _call_with_frames_removed\n",
      "  File \"/opt/homebrew/anaconda3/lib/python3.10/site-packages/numpy/testing/_private/utils.py\", line 57, in <module>\n",
      "    HAS_LAPACK64 = numpy.linalg._umath_linalg._ilp64\n",
      "AttributeError: module 'numpy.linalg' has no attribute '_umath_linalg'\n",
      "]\n",
      "[autoreload of numpy.testing failed: Traceback (most recent call last):\n",
      "  File \"/opt/homebrew/anaconda3/lib/python3.10/site-packages/IPython/extensions/autoreload.py\", line 261, in check\n",
      "  File \"/opt/homebrew/anaconda3/lib/python3.10/site-packages/IPython/extensions/autoreload.py\", line 459, in superreload\n",
      "  File \"/opt/homebrew/anaconda3/lib/python3.10/importlib/__init__.py\", line 169, in reload\n",
      "    _bootstrap._exec(spec, module)\n",
      "  File \"<frozen importlib._bootstrap>\", line 619, in _exec\n",
      "  File \"<frozen importlib._bootstrap_external>\", line 883, in exec_module\n",
      "  File \"<frozen importlib._bootstrap>\", line 241, in _call_with_frames_removed\n",
      "  File \"/opt/homebrew/anaconda3/lib/python3.10/site-packages/numpy/testing/__init__.py\", line 14, in <module>\n",
      "    from . import overrides\n",
      "  File \"/opt/homebrew/anaconda3/lib/python3.10/site-packages/numpy/testing/overrides.py\", line 6, in <module>\n",
      "    from numpy.core.overrides import ARRAY_FUNCTIONS as _array_functions\n",
      "ImportError: cannot import name 'ARRAY_FUNCTIONS' from 'numpy.core.overrides' (/opt/homebrew/anaconda3/lib/python3.10/site-packages/numpy/core/overrides.py)\n",
      "]\n"
     ]
    }
   ],
   "source": [
    "print(pd. __version__)"
   ]
  },
  {
   "cell_type": "code",
   "execution_count": null,
   "id": "2af7ad2f-740d-44a4-a070-251651060c4e",
   "metadata": {},
   "outputs": [],
   "source": []
  }
 ],
 "metadata": {
  "kernelspec": {
   "display_name": "Python 3 (ipykernel)",
   "language": "python",
   "name": "python3"
  },
  "language_info": {
   "codemirror_mode": {
    "name": "ipython",
    "version": 3
   },
   "file_extension": ".py",
   "mimetype": "text/x-python",
   "name": "python",
   "nbconvert_exporter": "python",
   "pygments_lexer": "ipython3",
   "version": "3.10.9"
  }
 },
 "nbformat": 4,
 "nbformat_minor": 5
}
